Workbook

Sheet Elo values
A1: Team | B1: Today | C1: end of 2024 | D1: end of 2023 | E1: end of 2022 | F1: end of 2021 | G1: end of 2020 | H1: end of 2019 | I1: end of 2018 | J1: end of 2017 | K1: end of 2016 | L1: end of 2015 | M1: end of 2014 | N1: end of 2013 | O1: end of 2012 | P1: end of 2011 | Q1: end of 2010 | R1: end of 2009
A2: Tipperary | B2: =LOOKUP($A2,'2026'!$AA$1:$CA$1,'2026'!$AA$2:$CB$2) -> 2290 | C2: =LOOKUP($A2,'2025'!$AA$1:$CA$1,'2025'!$AA$2:$CB$2) -> 1960 | D2: =LOOKUP($A2,'2024'!$AA$1:$CA$1,'2024'!$AA$2:$CB$2) -> 2031 | E2: =LOOKUP($A2,'2023'!$AA$1:$CA$1,'2023'!$AA$2:$CB$2) -> 1951 | F2: =LOOKUP($A2,'2022'!$AA$1:$CA$1,'2022'!$AA$2:$CB$2) -> 2116 | G2: =LOOKUP($A2,'2021'!$AA$1:$CA$1,'2021'!$AA$2:$CB$2) -> 2093 | H2: =LOOKUP($A2,'2020'!$AA$1:$CA$1,'2020'!$AA$2:$CB$2) -> 2222 | I2: =LOOKUP($A2,'2019'!$AA$1:$CA$1,'2019'!$AA$2:$CB$2) -> 2008 | J2: =LOOKUP($A2,'2018'!$AA$1:$CA$1,'2018'!$AA$2:$CB$2) -> 2139 | K2: =LOOKUP($A2,'2017'!$AA$1:$CA$1,'2017'!$AA$2:$CB$2) -> 2241 | L2: =LOOKUP($A2,'2016'!$AA$1:$CA$1,'2016'!$AA$2:$CA$2) -> 2101 | M2: =LOOKUP($A2,'2015'!$AA$1:$CA$1,'2015'!$AA$2:$CA$2) -> 2070 | N2: =LOOKUP($A2,'2014'!$AA$1:$BY$1,'2014'!$AA$2:$BY$2) -> 2005 | O2: =LOOKUP($A2,'2013'!$AA$1:$BX$1,'2013'!$AA$2:$BX$2) -> 2048 | P2: =LOOKUP($A2,'2012'!$AA$1:$BX$1,'2012'!$AA$2:$BX$2) -> 2110 | Q2: =LOOKUP($A2,'2011'!$AA$1:$BX$1,'2011'!$AA$2:$BX$2) -> 2107 | R2: =LOOKUP($A2,'2010'!$AA$1:$BX$1,'2010'!$AA$2:$BX$2) -> 1944
A3: Cork | B3: =LOOKUP($A3,'2026'!$AA$1:$CA$1,'2026'!$AA$2:$CB$2) -> 2242 | C3: =LOOKUP($A3,'2025'!$AA$1:$CA$1,'2025'!$AA$2:$CB$2) -> 2232 | D3: =LOOKUP($A3,'2024'!$AA$1:$CA$1,'2024'!$AA$2:$CB$2) -> 2104 | E3: =LOOKUP($A3,'2023'!$AA$1:$CA$1,'2023'!$AA$2:$CB$2) -> 2088 | F3: =LOOKUP($A3,'2022'!$AA$1:$CA$1,'2022'!$AA$2:$CB$2) -> 1985 | G3: =LOOKUP($A3,'2021'!$AA$1:$CA$1,'2021'!$AA$2:$CB$2) -> 1920 | H3: =LOOKUP($A3,'2020'!$AA$1:$CA$1,'2020'!$AA$2:$CB$2) -> 1969 | I3: =LOOKUP($A3,'2019'!$AA$1:$CA$1,'2019'!$AA$2:$CB$2) -> 1991 | J3: =LOOKUP($A3,'2018'!$AA$1:$CA$1,'2018'!$AA$2:$CB$2) -> 1969 | K3: =LOOKUP($A3,'2017'!$AA$1:$CA$1,'2017'!$AA$2:$CB$2) -> 1848 | L3: =LOOKUP($A3,'2016'!$AA$1:$CA$1,'2016'!$AA$2:$CA$2) -> 1939 | M3: =LOOKUP($A3,'2015'!$AA$1:$CA$1,'2015'!$AA$2:$CA$2) -> 1975 | N3: =LOOKUP($A3,'2014'!$AA$1:$BY$1,'2014'!$AA$2:$BY$2) -> 1954 | O3: =LOOKUP($A3,'2013'!$AA$1:$BX$1,'2013'!$AA$2:$BX$2) -> 1901 | P3: =LOOKUP($A3,'2012'!$AA$1:$BX$1,'2012'!$AA$2:$BX$2) -> 1796 | Q3: =LOOKUP($A3,'2011'!$AA$1:$BX$1,'2011'!$AA$2:$BX$2) -> 1844 | R3: =LOOKUP($A3,'2010'!$AA$1:$BX$1,'2010'!$AA$2:$BX$2) -> 1720
A4: Limerick | B4: =LOOKUP($A4,'2026'!$AA$1:$CA$1,'2026'!$AA$2:$CB$2) -> 2179 | C4: =LOOKUP($A4,'2025'!$AA$1:$CA$1,'2025'!$AA$2:$CB$2) -> 2337 | D4: =LOOKUP($A4,'2024'!$AA$1:$CA$1,'2024'!$AA$2:$CB$2) -> 2412 | E4: =LOOKUP($A4,'2023'!$AA$1:$CA$1,'2023'!$AA$2:$CB$2) -> 2356 | F4: =LOOKUP($A4,'2022'!$AA$1:$CA$1,'2022'!$AA$2:$CB$2) -> 2371 | G4: =LOOKUP($A4,'2021'!$AA$1:$CA$1,'2021'!$AA$2:$CB$2) -> 2353 | H4: =LOOKUP($A4,'2020'!$AA$1:$CA$1,'2020'!$AA$2:$CB$2) -> 2152 | I4: =LOOKUP($A4,'2019'!$AA$1:$CA$1,'2019'!$AA$2:$CB$2) -> 2161 | J4: =LOOKUP($A4,'2018'!$AA$1:$CA$1,'2018'!$AA$2:$CB$2) -> 1799 | K4: =LOOKUP($A4,'2017'!$AA$1:$CA$1,'2017'!$AA$2:$CB$2) -> 1854 | L4: =LOOKUP($A4,'2016'!$AA$1:$CA$1,'2016'!$AA$2:$CA$2) -> 1828 | M4: =LOOKUP($A4,'2015'!$AA$1:$CA$1,'2015'!$AA$2:$CA$2) -> 1897 | N4: =LOOKUP($A4,'2014'!$AA$1:$BY$1,'2014'!$AA$2:$BY$2) -> 1827 | O4: =LOOKUP($A4,'2013'!$AA$1:$BX$1,'2013'!$AA$2:$BX$2) -> 1766 | P4: =LOOKUP($A4,'2012'!$AA$1:$BX$1,'2012'!$AA$2:$BX$2) -> 1749 | Q4: =LOOKUP($A4,'2011'!$AA$1:$BX$1,'2011'!$AA$2:$BX$2) -> 1569 | R4: =LOOKUP($A4,'2010'!$AA$1:$BX$1,'2010'!$AA$2:$BX$2) -> 1778
A5: Clare | B5: =LOOKUP($A5,'2026'!$AA$1:$CA$1,'2026'!$AA$2:$CB$2) -> 2157 | C5: =LOOKUP($A5,'2025'!$AA$1:$CA$1,'2025'!$AA$2:$CB$2) -> 2294 | D5: =LOOKUP($A5,'2024'!$AA$1:$CA$1,'2024'!$AA$2:$CB$2) -> 2094 | E5: =LOOKUP($A5,'2023'!$AA$1:$CA$1,'2023'!$AA$2:$CB$2) -> 2015 | F5: =LOOKUP($A5,'2022'!$AA$1:$CA$1,'2022'!$AA$2:$CB$2) -> 1984 | G5: =LOOKUP($A5,'2021'!$AA$1:$CA$1,'2021'!$AA$2:$CB$2) -> 1988 | H5: =LOOKUP($A5,'2020'!$AA$1:$CA$1,'2020'!$AA$2:$CB$2) -> 1985 | I5: =LOOKUP($A5,'2019'!$AA$1:$CA$1,'2019'!$AA$2:$CB$2) -> 2048 | J5: =LOOKUP($A5,'2018'!$AA$1:$CA$1,'2018'!$AA$2:$CB$2) -> 1918 | K5: =LOOKUP($A5,'2017'!$AA$1:$CA$1,'2017'!$AA$2:$CB$2) -> 1934 | L5: =LOOKUP($A5,'2016'!$AA$1:$CA$1,'2016'!$AA$2:$CA$2) -> 1823 | M5: =LOOKUP($A5,'2015'!$AA$1:$CA$1,'2015'!$AA$2:$CA$2) -> 1912 | N5: =LOOKUP($A5,'2014'!$AA$1:$BY$1,'2014'!$AA$2:$BY$2) -> 2021 | O5: =LOOKUP($A5,'2013'!$AA$1:$BX$1,'2013'!$AA$2:$BX$2) -> 1711 | P5: =LOOKUP($A5,'2012'!$AA$1:$BX$1,'2012'!$AA$2:$BX$2) -> 1576 | Q5: =LOOKUP($A5,'2011'!$AA$1:$BX$1,'2011'!$AA$2:$BX$2) -> 1627 | R5: =LOOKUP($A5,'2010'!$AA$1:$BX$1,'2010'!$AA$2:$BX$2) -> 1622
A6: Kilkenny | B6: =LOOKUP($A6,'2026'!$AA$1:$CA$1,'2026'!$AA$2:$CB$2) -> 2125 | C6: =LOOKUP($A6,'2025'!$AA$1:$CA$1,'2025'!$AA$2:$CB$2) -> 2115 | D6: =LOOKUP($A6,'2024'!$AA$1:$CA$1,'2024'!$AA$2:$CB$2) -> 2146 | E6: =LOOKUP($A6,'2023'!$AA$1:$CA$1,'2023'!$AA$2:$CB$2) -> 2137 | F6: =LOOKUP($A6,'2022'!$AA$1:$CA$1,'2022'!$AA$2:$CB$2) -> 2048 | G6: =LOOKUP($A6,'2021'!$AA$1:$CA$1,'2021'!$AA$2:$CB$2) -> 2027 | H6: =LOOKUP($A6,'2020'!$AA$1:$CA$1,'2020'!$AA$2:$CB$2) -> 2020 | I6: =LOOKUP($A6,'2019'!$AA$1:$CA$1,'2019'!$AA$2:$CB$2) -> 2049 | J6: =LOOKUP($A6,'2018'!$AA$1:$CA$1,'2018'!$AA$2:$CB$2) -> 2023 | K6: =LOOKUP($A6,'2017'!$AA$1:$CA$1,'2017'!$AA$2:$CB$2) -> 2181 | L6: =LOOKUP($A6,'2016'!$AA$1:$CA$1,'2016'!$AA$2:$CA$2) -> 2265 | M6: =LOOKUP($A6,'2015'!$AA$1:$CA$1,'2015'!$AA$2:$CA$2) -> 2263 | N6: =LOOKUP($A6,'2014'!$AA$1:$BY$1,'2014'!$AA$2:$BY$2) -> 2129 | O6: =LOOKUP($A6,'2013'!$AA$1:$BX$1,'2013'!$AA$2:$BX$2) -> 2280 | P6: =LOOKUP($A6,'2012'!$AA$1:$BX$1,'2012'!$AA$2:$BX$2) -> 2207 | Q6: =LOOKUP($A6,'2011'!$AA$1:$BX$1,'2011'!$AA$2:$BX$2) -> 2085 | R6: =LOOKUP($A6,'2010'!$AA$1:$BX$1,'2010'!$AA$2:$BX$2) -> 2096
A7: Galway | B7: =LOOKUP($A7,'2026'!$AA$1:$CA$1,'2026'!$AA$2:$CB$2) -> 2017 | C7: =LOOKUP($A7,'2025'!$AA$1:$CA$1,'2025'!$AA$2:$CB$2) -> 2025 | D7: =LOOKUP($A7,'2024'!$AA$1:$CA$1,'2024'!$AA$2:$CB$2) -> 2118 | E7: =LOOKUP($A7,'2023'!$AA$1:$CA$1,'2023'!$AA$2:$CB$2) -> 2098 | F7: =LOOKUP($A7,'2022'!$AA$1:$CA$1,'2022'!$AA$2:$CB$2) -> 2076 | G7: =LOOKUP($A7,'2021'!$AA$1:$CA$1,'2021'!$AA$2:$CB$2) -> 2131 | H7: =LOOKUP($A7,'2020'!$AA$1:$CA$1,'2020'!$AA$2:$CB$2) -> 2131 | I7: =LOOKUP($A7,'2019'!$AA$1:$CA$1,'2019'!$AA$2:$CB$2) -> 2230 | J7: =LOOKUP($A7,'2018'!$AA$1:$CA$1,'2018'!$AA$2:$CB$2) -> 2255 | K7: =LOOKUP($A7,'2017'!$AA$1:$CA$1,'2017'!$AA$2:$CB$2) -> 2005 | L7: =LOOKUP($A7,'2016'!$AA$1:$CA$1,'2016'!$AA$2:$CA$2) -> 2030 | M7: =LOOKUP($A7,'2015'!$AA$1:$CA$1,'2015'!$AA$2:$CA$2) -> 1920 | N7: =LOOKUP($A7,'2014'!$AA$1:$BY$1,'2014'!$AA$2:$BY$2) -> 1903 | O7: =LOOKUP($A7,'2013'!$AA$1:$BX$1,'2013'!$AA$2:$BX$2) -> 2035 | P7: =LOOKUP($A7,'2012'!$AA$1:$BX$1,'2012'!$AA$2:$BX$2) -> 1873 | Q7: =LOOKUP($A7,'2011'!$AA$1:$BX$1,'2011'!$AA$2:$BX$2) -> 1925 | R7: =LOOKUP($A7,'2010'!$AA$1:$BX$1,'2010'!$AA$2:$BX$2) -> 1872
A8: Wexford | B8: =LOOKUP($A8,'2026'!$AA$1:$CA$1,'2026'!$AA$2:$CB$2) -> 1989 | C8: =LOOKUP($A8,'2025'!$AA$1:$CA$1,'2025'!$AA$2:$CB$2) -> 1949 | D8: =LOOKUP($A8,'2024'!$AA$1:$CA$1,'2024'!$AA$2:$CB$2) -> 1855 | E8: =LOOKUP($A8,'2023'!$AA$1:$CA$1,'2023'!$AA$2:$CB$2) -> 1972 | F8: =LOOKUP($A8,'2022'!$AA$1:$CA$1,'2022'!$AA$2:$CB$2) -> 1904 | G8: =LOOKUP($A8,'2021'!$AA$1:$CA$1,'2021'!$AA$2:$CB$2) -> 1925 | H8: =LOOKUP($A8,'2020'!$AA$1:$CA$1,'2020'!$AA$2:$CB$2) -> 1969 | I8: =LOOKUP($A8,'2019'!$AA$1:$CA$1,'2019'!$AA$2:$CB$2) -> 1897 | J8: =LOOKUP($A8,'2018'!$AA$1:$CA$1,'2018'!$AA$2:$CB$2) -> 1858 | K8: =LOOKUP($A8,'2017'!$AA$1:$CA$1,'2017'!$AA$2:$CB$2) -> 1672 | L8: =LOOKUP($A8,'2016'!$AA$1:$CA$1,'2016'!$AA$2:$CA$2) -> 1669 | M8: =LOOKUP($A8,'2015'!$AA$1:$CA$1,'2015'!$AA$2:$CA$2) -> 1662 | N8: =LOOKUP($A8,'2014'!$AA$1:$BY$1,'2014'!$AA$2:$BY$2) -> 1553 | O8: =LOOKUP($A8,'2013'!$AA$1:$BX$1,'2013'!$AA$2:$BX$2) -> 1571 | P8: =LOOKUP($A8,'2012'!$AA$1:$BX$1,'2012'!$AA$2:$BX$2) -> 1592 | Q8: =LOOKUP($A8,'2011'!$AA$1:$BX$1,'2011'!$AA$2:$BX$2) -> 1628 | R8: =LOOKUP($A8,'2010'!$AA$1:$BX$1,'2010'!$AA$2:$BX$2) -> 1564
A9: Waterford | B9: =LOOKUP($A9,'2026'!$AA$1:$CA$1,'2026'!$AA$2:$CB$2) -> 1950 | C9: =LOOKUP($A9,'2025'!$AA$1:$CA$1,'2025'!$AA$2:$CB$2) -> 1920 | D9: =LOOKUP($A9,'2024'!$AA$1:$CA$1,'2024'!$AA$2:$CB$2) -> 1974 | E9: =LOOKUP($A9,'2023'!$AA$1:$CA$1,'2023'!$AA$2:$CB$2) -> 2011 | F9: =LOOKUP($A9,'2022'!$AA$1:$CA$1,'2022'!$AA$2:$CB$2) -> 2018 | G9: =LOOKUP($A9,'2021'!$AA$1:$CA$1,'2021'!$AA$2:$CB$2) -> 2012 | H9: =LOOKUP($A9,'2020'!$AA$1:$CA$1,'2020'!$AA$2:$CB$2) -> 1847 | I9: =LOOKUP($A9,'2019'!$AA$1:$CA$1,'2019'!$AA$2:$CB$2) -> 1908 | J9: =LOOKUP($A9,'2018'!$AA$1:$CA$1,'2018'!$AA$2:$CB$2) -> 2105 | K9: =LOOKUP($A9,'2017'!$AA$1:$CA$1,'2017'!$AA$2:$CB$2) -> 2056 | L9: =LOOKUP($A9,'2016'!$AA$1:$CA$1,'2016'!$AA$2:$CA$2) -> 1978 | M9: =LOOKUP($A9,'2015'!$AA$1:$CA$1,'2015'!$AA$2:$CA$2) -> 1756 | N9: =LOOKUP($A9,'2014'!$AA$1:$BY$1,'2014'!$AA$2:$BY$2) -> 1845 | O9: =LOOKUP($A9,'2013'!$AA$1:$BX$1,'2013'!$AA$2:$BX$2) -> 1858 | P9: =LOOKUP($A9,'2012'!$AA$1:$BX$1,'2012'!$AA$2:$BX$2) -> 1925 | Q9: =LOOKUP($A9,'2011'!$AA$1:$BX$1,'2011'!$AA$2:$BX$2) -> 1873 | R9: =LOOKUP($A9,'2010'!$AA$1:$BX$1,'2010'!$AA$2:$BX$2) -> 1836
A10: Dublin | B10: =LOOKUP($A10,'2026'!$AA$1:$CA$1,'2026'!$AA$2:$CB$2) -> 1942 | C10: =LOOKUP($A10,'2025'!$AA$1:$CA$1,'2025'!$AA$2:$CB$2) -> 1867 | D10: =LOOKUP($A10,'2024'!$AA$1:$CA$1,'2024'!$AA$2:$CB$2) -> 1844 | E10: =LOOKUP($A10,'2023'!$AA$1:$CA$1,'2023'!$AA$2:$CB$2) -> 1823 | F10: =LOOKUP($A10,'2022'!$AA$1:$CA$1,'2022'!$AA$2:$CB$2) -> 1752 | G10: =LOOKUP($A10,'2021'!$AA$1:$CA$1,'2021'!$AA$2:$CB$2) -> 1768 | H10: =LOOKUP($A10,'2020'!$AA$1:$CA$1,'2020'!$AA$2:$CB$2) -> 1832 | I10: =LOOKUP($A10,'2019'!$AA$1:$CA$1,'2019'!$AA$2:$CB$2) -> 1736 | J10: =LOOKUP($A10,'2018'!$AA$1:$CA$1,'2018'!$AA$2:$CB$2) -> 1813 | K10: =LOOKUP($A10,'2017'!$AA$1:$CA$1,'2017'!$AA$2:$CB$2) -> 1887 | L10: =LOOKUP($A10,'2016'!$AA$1:$CA$1,'2016'!$AA$2:$CA$2) -> 1872 | M10: =LOOKUP($A10,'2015'!$AA$1:$CA$1,'2015'!$AA$2:$CA$2) -> 1868 | N10: =LOOKUP($A10,'2014'!$AA$1:$BY$1,'2014'!$AA$2:$BY$2) -> 1901 | O10: =LOOKUP($A10,'2013'!$AA$1:$BX$1,'2013'!$AA$2:$BX$2) -> 1771 | P10: =LOOKUP($A10,'2012'!$AA$1:$BX$1,'2012'!$AA$2:$BX$2) -> 1887 | Q10: =LOOKUP($A10,'2011'!$AA$1:$BX$1,'2011'!$AA$2:$BX$2) -> 1686 | R10: =LOOKUP($A10,'2010'!$AA$1:$BX$1,'2010'!$AA$2:$BX$2) -> 1759
A11: Offaly | B11: =LOOKUP($A11,'2026'!$AA$1:$CA$1,'2026'!$AA$2:$CB$2) -> 1629 | C11: =LOOKUP($A11,'2025'!$AA$1:$CA$1,'2025'!$AA$2:$CB$2) -> 1592 | D11: =LOOKUP($A11,'2024'!$AA$1:$CA$1,'2024'!$AA$2:$CB$2) -> 1510 | E11: =LOOKUP($A11,'2023'!$AA$1:$CA$1,'2023'!$AA$2:$CB$2) -> 1481 | F11: =LOOKUP($A11,'2022'!$AA$1:$CA$1,'2022'!$AA$2:$CB$2) -> 1542 | G11: =LOOKUP($A11,'2021'!$AA$1:$CA$1,'2021'!$AA$2:$CB$2) -> 1385 | H11: =LOOKUP($A11,'2020'!$AA$1:$CA$1,'2020'!$AA$2:$CB$2) -> 1308 | I11: =LOOKUP($A11,'2019'!$AA$1:$CA$1,'2019'!$AA$2:$CB$2) -> 1442 | J11: =LOOKUP($A11,'2018'!$AA$1:$CA$1,'2018'!$AA$2:$CB$2) -> 1478 | K11: =LOOKUP($A11,'2017'!$AA$1:$CA$1,'2017'!$AA$2:$CB$2) -> 1546 | L11: =LOOKUP($A11,'2016'!$AA$1:$CA$1,'2016'!$AA$2:$CA$2) -> 1539 | M11: =LOOKUP($A11,'2015'!$AA$1:$CA$1,'2015'!$AA$2:$CA$2) -> 1564 | N11: =LOOKUP($A11,'2014'!$AA$1:$BY$1,'2014'!$AA$2:$BY$2) -> 1553 | O11: =LOOKUP($A11,'2013'!$AA$1:$BX$1,'2013'!$AA$2:$BX$2) -> 1558 | P11: =LOOKUP($A11,'2012'!$AA$1:$BX$1,'2012'!$AA$2:$BX$2) -> 1553 | Q11: =LOOKUP($A11,'2011'!$AA$1:$BX$1,'2011'!$AA$2:$BX$2) -> 1651 | R11: =LOOKUP($A11,'2010'!$AA$1:$BX$1,'2010'!$AA$2:$BX$2) -> 1621
A12: Carlow | B12: =LOOKUP($A12,'2026'!$AA$1:$CA$1,'2026'!$AA$2:$CB$2) -> 1513 | C12: =LOOKUP($A12,'2025'!$AA$1:$CA$1,'2025'!$AA$2:$CB$2) -> 1428 | D12: =LOOKUP($A12,'2024'!$AA$1:$CA$1,'2024'!$AA$2:$CB$2) -> 1477 | E12: =LOOKUP($A12,'2023'!$AA$1:$CA$1,'2023'!$AA$2:$CB$2) -> 1419 | F12: =LOOKUP($A12,'2022'!$AA$1:$CA$1,'2022'!$AA$2:$CB$2) -> 1414 | G12: =LOOKUP($A12,'2021'!$AA$1:$CA$1,'2021'!$AA$2:$CB$2) -> 1418 | H12: =LOOKUP($A12,'2020'!$AA$1:$CA$1,'2020'!$AA$2:$CB$2) -> 1459 | I12: =LOOKUP($A12,'2019'!$AA$1:$CA$1,'2019'!$AA$2:$CB$2) -> 1542 | J12: =LOOKUP($A12,'2018'!$AA$1:$CA$1,'2018'!$AA$2:$CB$2) -> 1394 | K12: =LOOKUP($A12,'2017'!$AA$1:$CA$1,'2017'!$AA$2:$CB$2) -> 1287 | L12: =LOOKUP($A12,'2016'!$AA$1:$CA$1,'2016'!$AA$2:$CA$2) -> 1303 | M12: =LOOKUP($A12,'2015'!$AA$1:$CA$1,'2015'!$AA$2:$CA$2) -> 1286 | N12: =LOOKUP($A12,'2014'!$AA$1:$BY$1,'2014'!$AA$2:$BY$2) -> 1275 | O12: =LOOKUP($A12,'2013'!$AA$1:$BX$1,'2013'!$AA$2:$BX$2) -> 1373 | P12: =LOOKUP($A12,'2012'!$AA$1:$BX$1,'2012'!$AA$2:$BX$2) -> 1370 | Q12: =LOOKUP($A12,'2011'!$AA$1:$BX$1,'2011'!$AA$2:$BX$2) -> 1488 | R12: =LOOKUP($A12,'2010'!$AA$1:$BX$1,'2010'!$AA$2:$BX$2) -> 1591
A13: Kildare | B13: =LOOKUP($A13,'2026'!$AA$1:$CA$1,'2026'!$AA$2:$CB$2) -> 1492 | C13: =LOOKUP($A13,'2025'!$AA$1:$CA$1,'2025'!$AA$2:$CB$2) -> 1364 | D13: =LOOKUP($A13,'2024'!$AA$1:$CA$1,'2024'!$AA$2:$CB$2) -> 1219 | E13: =LOOKUP($A13,'2023'!$AA$1:$CA$1,'2023'!$AA$2:$CB$2) -> 1296 | F13: =LOOKUP($A13,'2022'!$AA$1:$CA$1,'2022'!$AA$2:$CB$2) -> 1158 | G13: =LOOKUP($A13,'2021'!$AA$1:$CA$1,'2021'!$AA$2:$CB$2) -> 1167 | H13: =LOOKUP($A13,'2020'!$AA$1:$CA$1,'2020'!$AA$2:$CB$2) -> 1072 | I13: =LOOKUP($A13,'2019'!$AA$1:$CA$1,'2019'!$AA$2:$CB$2) -> 1164 | J13: =LOOKUP($A13,'2018'!$AA$1:$CA$1,'2018'!$AA$2:$CB$2) -> 1153 | K13: =LOOKUP($A13,'2017'!$AA$1:$CA$1,'2017'!$AA$2:$CB$2) -> 1158 | L13: =LOOKUP($A13,'2016'!$AA$1:$CA$1,'2016'!$AA$2:$CA$2) -> 1293 | M13: =LOOKUP($A13,'2015'!$AA$1:$CA$1,'2015'!$AA$2:$CA$2) -> 1246 | N13: =LOOKUP($A13,'2014'!$AA$1:$BY$1,'2014'!$AA$2:$BY$2) -> 1177 | O13: =LOOKUP($A13,'2013'!$AA$1:$BX$1,'2013'!$AA$2:$BX$2) -> 1261 | P13: =LOOKUP($A13,'2012'!$AA$1:$BX$1,'2012'!$AA$2:$BX$2) -> 1195 | Q13: =LOOKUP($A13,'2011'!$AA$1:$BX$1,'2011'!$AA$2:$BX$2) -> 1175 | R13: =LOOKUP($A13,'2010'!$AA$1:$BX$1,'2010'!$AA$2:$BX$2) -> 1129
... A37: Warwickshire | B37: =LOOKUP($A37,'2026'!$AA$1:$CA$1,'2026'!$AA$2:$CB$2) -> 153 | C37: =LOOKUP($A37,'2025'!$AA$1:$CA$1,'2025'!$AA$2:$CB$2) -> 237 | D37: =LOOKUP($A37,'2024'!$AA$1:$CA$1,'2024'!$AA$2:$CB$2) -> 195 | E37: =LOOKUP($A37,'2023'!$AA$1:$CA$1,'2023'!$AA$2:$CB$2) -> 450 | F37: =LOOKUP($A37,'2022'!$AA$1:$CA$1,'2022'!$AA$2:$CB$2) -> 712 | G37: =LOOKUP($A37,'2021'!$AA$1:$CA$1,'2021'!$AA$2:$CB$2) -> 712 | H37: =LOOKUP($A37,'2020'!$AA$1:$CA$1,'2020'!$AA$2:$CB$2) -> 780 | I37: =LOOKUP($A37,'2019'!$AA$1:$CA$1,'2019'!$AA$2:$CB$2) -> 879 | J37: =LOOKUP($A37,'2018'!$AA$1:$CA$1,'2018'!$AA$2:$CB$2) -> 690 | K37: =LOOKUP($A37,'2017'!$AA$1:$CA$1,'2017'!$AA$2:$CB$2) -> 559 | L37: =LOOKUP($A37,'2016'!$AA$1:$CA$1,'2016'!$AA$2:$CA$2) -> 522 | M37: =LOOKUP($A37,'2015'!$AA$1:$CA$1,'2015'!$AA$2:$CA$2) -> 530 | N37: =LOOKUP($A37,'2014'!$AA$1:$BY$1,'2014'!$AA$2:$BY$2) -> 605 | O37: =LOOKUP($A37,'2013'!$AA$1:$BX$1,'2013'!$AA$2:$BX$2) -> 567 | P37: =LOOKUP($A37,'2012'!$AA$1:$BX$1,'2012'!$AA$2:$BX$2) -> 558 | Q37: =LOOKUP($A37,'2011'!$AA$1:$BX$1,'2011'!$AA$2:$BX$2) -> 528 | R37: =LOOKUP($A37,'2010'!$AA$1:$BX$1,'2010'!$AA$2:$BX$2) -> 547
A38: Lancashire | B38: =LOOKUP($A38,'2026'!$AA$1:$CA$1,'2026'!$AA$2:$CB$2) -> 89 | C38: =LOOKUP($A38,'2025'!$AA$1:$CA$1,'2025'!$AA$2:$CB$2) -> 136 | D38: =LOOKUP($A38,'2024'!$AA$1:$CA$1,'2024'!$AA$2:$CB$2) -> 278 | E38: =LOOKUP($A38,'2023'!$AA$1:$CA$1,'2023'!$AA$2:$CB$2) -> 262 | F38: =LOOKUP($A38,'2022'!$AA$1:$CA$1,'2022'!$AA$2:$CB$2) -> 424 | G38: =LOOKUP($A38,'2021'!$AA$1:$CA$1,'2021'!$AA$2:$CB$2) -> 424 | H38: =LOOKUP($A38,'2020'!$AA$1:$CA$1,'2020'!$AA$2:$CB$2) -> 395 | I38: =LOOKUP($A38,'2019'!$AA$1:$CA$1,'2019'!$AA$2:$CB$2) -> 379 | J38: =LOOKUP($A38,'2018'!$AA$1:$CA$1,'2018'!$AA$2:$CB$2) -> 197 | K38: =LOOKUP($A38,'2017'!$AA$1:$CA$1,'2017'!$AA$2:$CB$2) -> 159 | L38: =LOOKUP($A38,'2016'!$AA$1:$CA$1,'2016'!$AA$2:$CA$2) -> 216 | M38: 0 | N38: 0 | O38: 0 | P38: 0 | Q38: 0 | R38: 0

Sheet 2025
A1: Date | B1: Grade | D1: Team 1 | E1: Elo | F1: G | G1: P | H1: Sc | J1: Team 2 | K1: Elo | L1: G | M1: P | N1: Sc | P1: Home? | R1: Margin* | S1: Weight | U1: T1 win odds | V1: Result T1 | W1: Result T2 | AA1: Antrim | AB1: Armagh | AC1: Carlow | AD1: Cavan | AE1: Clare | AF1: Cork | AG1: Derry | AH1: Donegal | AI1: Down | AJ1: Dublin | AK1: Fermanagh | AL1: Fingal | AM1: Galway | AN1: Kerry | AO1: Kildare | AP1: Kilkenny | AQ1: Lancashire | AR1: Laois | AS1: Leitrim | AT1: Limerick | AU1: London | AV1: Longford | AW1: Louth | AX1: Mayo | AY1: Meath | AZ1: Monaghan | BA1: New York | BB1: Offaly | BC1: Roscommon | BD1: Sligo | BE1: South Down | BF1: Tipperary | BG1: Tyrone | BH1: Warwickshire | BI1: Waterford | BJ1: Westmeath | BK1: Wexford | BL1: Wicklow
Z2: opening | AA2: =LOOKUP(9.999E+307,'2024'!AA:AA) -> 1549 | AB2: =LOOKUP(9.999E+307,'2024'!AB:AB) -> 605 | AC2: =LOOKUP(9.999E+307,'2024'!AC:AC) -> 1428 | AD2: =LOOKUP(9.999E+307,'2024'!AD:AD) -> 377 | AE2: =LOOKUP(9.999E+307,'2024'!AE:AE) -> 2294 | AF2: =LOOKUP(9.999E+307,'2024'!AF:AF) -> 2232 | AG2: =LOOKUP(9.999E+307,'2024'!AG:AG) -> 1198 | AH2: =LOOKUP(9.999E+307,'2024'!AH:AH) -> 1104 | AI2: =LOOKUP(9.999E+307,'2024'!AI:AI) -> 1191 | AJ2: =LOOKUP(9.999E+307,'2024'!AJ:AJ) -> 1867 | AK2: =LOOKUP(9.999E+307,'2024'!AK:AK) -> 570 | AL2: =LOOKUP(9.999E+307,'2024'!AL:AL) -> 717 | AM2: =LOOKUP(9.999E+307,'2024'!AM:AM) -> 2025 | AN2: =LOOKUP(9.999E+307,'2024'!AN:AN) -> 1331 | AO2: =LOOKUP(9.999E+307,'2024'!AO:AO) -> 1364 | AP2: =LOOKUP(9.999E+307,'2024'!AP:AP) -> 2115 | AQ2: =LOOKUP(9.999E+307,'2024'!AQ:AQ) -> 136 | AR2: =LOOKUP(9.999E+307,'2024'!AR:AR) -> 1521 | AS2: =LOOKUP(9.999E+307,'2024'!AS:AS) -> 228 | AT2: =LOOKUP(9.999E+307,'2024'!AT:AT) -> 2337 | AU2: =LOOKUP(9.999E+307,'2024'!AU:AU) -> 981 | AV2: =LOOKUP(9.999E+307,'2024'!AV:AV) -> 401 | AW2: =LOOKUP(9.999E+307,'2024'!AW:AW) -> 435 | AX2: =LOOKUP(9.999E+307,'2024'!AX:AX) -> 895 | AY2: =LOOKUP(9.999E+307,'2024'!AY:AY) -> 1089 | AZ2: =LOOKUP(9.999E+307,'2024'!AZ:AZ) -> 413 | BA2: =400 -> 400 | BB2: =LOOKUP(9.999E+307,'2024'!BB:BB) -> 1592 | BC2: =LOOKUP(9.999E+307,'2024'!BC:BC) -> 798 | BD2: =LOOKUP(9.999E+307,'2024'!BD:BD) -> 716 | BE2: =LOOKUP(9.999E+307,'2024'!BE:BE) -> 638 | BF2: =LOOKUP(9.999E+307,'2024'!BF:BF) -> 1960 | BG2: =LOOKUP(9.999E+307,'2024'!BG:BG) -> 885 | BH2: =LOOKUP(9.999E+307,'2024'!BH:BH) -> 237 | BI2: =LOOKUP(9.999E+307,'2024'!BI:BI) -> 1920 | BJ2: =LOOKUP(9.999E+307,'2024'!BJ:BJ) -> 1514 | BK2: =LOOKUP(9.999E+307,'2024'!BK:BK) -> 1949 | BL2: =LOOKUP(9.999E+307,'2024'!BL:BL) -> 822
A3: 45682 | B3: League | D3: Wexford | E3: =HLOOKUP(D3,AA$1:CB$10081,ROW()-1,FALSE) -> 1949 | F3: 0 | G3: 12 | H3: =F3*3+G3 -> 12 | J3: Cork | K3: =HLOOKUP(J3,AA$1:CB$10081,ROW()-1,FALSE) -> 2232 | L3: 2 | M3: 21 | N3: =L3*3+M3 -> 27 | P3: Y | R3: =MIN(Rules!$E$2,(MAX(H3/N3,N3/H3))) -> 2 | S3: =VLOOKUP(B3,Rules!A:B,2,FALSE) -> 40 | U3: =1/(10^(-(E3+(IF(P3="Y",Rules!$I$2,0))-K3)/Rules!$E$12)+1) -> 0.35149194 | V3: =ROUND(IF(H3>N3,(S3*R3*(1-U3)),IF(H3<N3,(S3*R3*(0-U3)),S3*R3*(0.5-U3))),0) -> -28 | W3: =-1*V3 -> 28 | AA3: =IF($D3=AA$1,$E3+$V3,(IF($J3=AA$1,$K3+$W3,AA2))) -> 1549 | AB3: =IF($D3=AB$1,$E3+$V3,(IF($J3=AB$1,$K3+$W3,AB2))) -> 605 | AC3: =IF($D3=AC$1,$E3+$V3,(IF($J3=AC$1,$K3+$W3,AC2))) -> 1428 | AD3: =IF($D3=AD$1,$E3+$V3,(IF($J3=AD$1,$K3+$W3,AD2))) -> 377 | AE3: =IF($D3=AE$1,$E3+$V3,(IF($J3=AE$1,$K3+$W3,AE2))) -> 2294 | AF3: =IF($D3=AF$1,$E3+$V3,(IF($J3=AF$1,$K3+$W3,AF2))) -> 2260 | AG3: =IF($D3=AG$1,$E3+$V3,(IF($J3=AG$1,$K3+$W3,AG2))) -> 1198 | AH3: =IF($D3=AH$1,$E3+$V3,(IF($J3=AH$1,$K3+$W3,AH2))) -> 1104 | ... BL3: =IF($D3=BL$1,$E3+$V3,(IF($J3=BL$1,$K3+$W3,BL2))) -> 822
A4: 45682 | B4: League | D4: Offaly | E4: =HLOOKUP(D4,AA$1:CB$10081,ROW()-1,FALSE) -> 1592 | F4: 0 | G4: 19 | H4: =F4*3+G4 -> 19 | J4: Carlow | K4: =HLOOKUP(J4,AA$1:CB$10081,ROW()-1,FALSE) -> 1428 | L4: 1 | M4: 16 | N4: =L4*3+M4 -> 19 | P4: Y | R4: =MIN(Rules!$E$2,(MAX(H4/N4,N4/H4))) -> 1 | S4: =VLOOKUP(B4,Rules!A:B,2,FALSE) -> 40 | U4: =1/(10^(-(E4+(IF(P4="Y",Rules!$I$2,0))-K4)/Rules!$E$12)+1) -> 0.80938568 | V4: =ROUND(IF(H4>N4,(S4*R4*(1-U4)),IF(H4<N4,(S4*R4*(0-U4)),S4*R4*(0.5-U4))),0) -> -12 | W4: =-1*V4 -> 12 | AA4: =IF($D4=AA$1,$E4+$V4,(IF($J4=AA$1,$K4+$W4,AA3))) -> 1549 | AB4: =IF($D4=AB$1,$E4+$V4,(IF($J4=AB$1,$K4+$W4,AB3))) -> 605 | AC4: =IF($D4=AC$1,$E4+$V4,(IF($J4=AC$1,$K4+$W4,AC3))) -> 1440 | AD4: =IF($D4=AD$1,$E4+$V4,(IF($J4=AD$1,$K4+$W4,AD3))) -> 377 | AE4: =IF($D4=AE$1,$E4+$V4,(IF($J4=AE$1,$K4+$W4,AE3))) -> 2294 | AF4: =IF($D4=AF$1,$E4+$V4,(IF($J4=AF$1,$K4+$W4,AF3))) -> 2260 | AG4: =IF($D4=AG$1,$E4+$V4,(IF($J4=AG$1,$K4+$W4,AG3))) -> 1198 | AH4: =IF($D4=AH$1,$E4+$V4,(IF($J4=AH$1,$K4+$W4,AH3))) -> 1104 | ... BL4: =IF($D4=BL$1,$E4+$V4,(IF($J4=BL$1,$K4+$W4,BL3))) -> 822
A5: 45682 | B5: League | D5: Dublin | E5: =HLOOKUP(D5,AA$1:CB$10081,ROW()-1,FALSE) -> 1867 | F5: 1 | G5: 25 | H5: =F5*3+G5 -> 28 | J5: Antrim | K5: =HLOOKUP(J5,AA$1:CB$10081,ROW()-1,FALSE) -> 1549 | L5: 2 | M5: 14 | N5: =L5*3+M5 -> 20 | P5: Y | R5: =MIN(Rules!$E$2,(MAX(H5/N5,N5/H5))) -> 1.4 | S5: =VLOOKUP(B5,Rules!A:B,2,FALSE) -> 40 | U5: =1/(10^(-(E5+(IF(P5="Y",Rules!$I$2,0))-K5)/Rules!$E$12)+1) -> 0.89615553 | V5: =ROUND(IF(H5>N5,(S5*R5*(1-U5)),IF(H5<N5,(S5*R5*(0-U5)),S5*R5*(0.5-U5))),0) -> 6 | W5: =-1*V5 -> -6 | AA5: =IF($D5=AA$1,$E5+$V5,(IF($J5=AA$1,$K5+$W5,AA4))) -> 1543 | AB5: =IF($D5=AB$1,$E5+$V5,(IF($J5=AB$1,$K5+$W5,AB4))) -> 605 | AC5: =IF($D5=AC$1,$E5+$V5,(IF($J5=AC$1,$K5+$W5,AC4))) -> 1440 | AD5: =IF($D5=AD$1,$E5+$V5,(IF($J5=AD$1,$K5+$W5,AD4))) -> 377 | AE5: =IF($D5=AE$1,$E5+$V5,(IF($J5=AE$1,$K5+$W5,AE4))) -> 2294 | AF5: =IF($D5=AF$1,$E5+$V5,(IF($J5=AF$1,$K5+$W5,AF4))) -> 2260 | AG5: =IF($D5=AG$1,$E5+$V5,(IF($J5=AG$1,$K5+$W5,AG4))) -> 1198 | AH5: =IF($D5=AH$1,$E5+$V5,(IF($J5=AH$1,$K5+$W5,AH4))) -> 1104 | ... BL5: =IF($D5=BL$1,$E5+$V5,(IF($J5=BL$1,$K5+$W5,BL4))) -> 822
A6: 45682 | B6: League | D6: Down | E6: =HLOOKUP(D6,AA$1:CB$10081,ROW()-1,FALSE) -> 1191 | F6: 2 | G6: 19 | H6: =F6*3+G6 -> 25 | J6: Kildare | K6: =HLOOKUP(J6,AA$1:CB$10081,ROW()-1,FALSE) -> 1364 | L6: 0 | M6: 22 | N6: =L6*3+M6 -> 22 | P6: Y | R6: =MIN(Rules!$E$2,(MAX(H6/N6,N6/H6))) -> 1.1363636 | S6: =VLOOKUP(B6,Rules!A:B,2,FALSE) -> 40 | U6: =1/(10^(-(E6+(IF(P6="Y",Rules!$I$2,0))-K6)/Rules!$E$12)+1) -> 0.473545 | V6: =ROUND(IF(H6>N6,(S6*R6*(1-U6)),IF(H6<N6,(S6*R6*(0-U6)),S6*R6*(0.5-U6))),0) -> 24 | W6: =-1*V6 -> -24 | AA6: =IF($D6=AA$1,$E6+$V6,(IF($J6=AA$1,$K6+$W6,AA5))) -> 1543 | AB6: =IF($D6=AB$1,$E6+$V6,(IF($J6=AB$1,$K6+$W6,AB5))) -> 605 | AC6: =IF($D6=AC$1,$E6+$V6,(IF($J6=AC$1,$K6+$W6,AC5))) -> 1440 | AD6: =IF($D6=AD$1,$E6+$V6,(IF($J6=AD$1,$K6+$W6,AD5))) -> 377 | AE6: =IF($D6=AE$1,$E6+$V6,(IF($J6=AE$1,$K6+$W6,AE5))) -> 2294 | AF6: =IF($D6=AF$1,$E6+$V6,(IF($J6=AF$1,$K6+$W6,AF5))) -> 2260 | AG6: =IF($D6=AG$1,$E6+$V6,(IF($J6=AG$1,$K6+$W6,AG5))) -> 1198 | AH6: =IF($D6=AH$1,$E6+$V6,(IF($J6=AH$1,$K6+$W6,AH5))) -> 1104 | ... BL6: =IF($D6=BL$1,$E6+$V6,(IF($J6=BL$1,$K6+$W6,BL5))) -> 822
A7: 45682 | B7: League | D7: Tyrone | E7: =HLOOKUP(D7,AA$1:CB$10081,ROW()-1,FALSE) -> 885 | F7: 0 | G7: 14 | H7: =F7*3+G7 -> 14 | J7: Derry | K7: =HLOOKUP(J7,AA$1:CB$10081,ROW()-1,FALSE) -> 1198 | L7: 1 | M7: 13 | N7: =L7*3+M7 -> 16 | P7: Y | R7: =MIN(Rules!$E$2,(MAX(H7/N7,N7/H7))) -> 1.1428571 | S7: =VLOOKUP(B7,Rules!A:B,2,FALSE) -> 40 | U7: =1/(10^(-(E7+(IF(P7="Y",Rules!$I$2,0))-K7)/Rules!$E$12)+1) -> 0.32068127 | V7: =ROUND(IF(H7>N7,(S7*R7*(1-U7)),IF(H7<N7,(S7*R7*(0-U7)),S7*R7*(0.5-U7))),0) -> -15 | W7: =-1*V7 -> 15 | AA7: =IF($D7=AA$1,$E7+$V7,(IF($J7=AA$1,$K7+$W7,AA6))) -> 1543 | AB7: =IF($D7=AB$1,$E7+$V7,(IF($J7=AB$1,$K7+$W7,AB6))) -> 605 | AC7: =IF($D7=AC$1,$E7+$V7,(IF($J7=AC$1,$K7+$W7,AC6))) -> 1440 | AD7: =IF($D7=AD$1,$E7+$V7,(IF($J7=AD$1,$K7+$W7,AD6))) -> 377 | AE7: =IF($D7=AE$1,$E7+$V7,(IF($J7=AE$1,$K7+$W7,AE6))) -> 2294 | AF7: =IF($D7=AF$1,$E7+$V7,(IF($J7=AF$1,$K7+$W7,AF6))) -> 2260 | AG7: =IF($D7=AG$1,$E7+$V7,(IF($J7=AG$1,$K7+$W7,AG6))) -> 1213 | AH7: =IF($D7=AH$1,$E7+$V7,(IF($J7=AH$1,$K7+$W7,AH6))) -> 1104 | ... BL7: =IF($D7=BL$1,$E7+$V7,(IF($J7=BL$1,$K7+$W7,BL6))) -> 822
A8: 45682 | B8: League | D8: Louth | E8: =HLOOKUP(D8,AA$1:CB$10081,ROW()-1,FALSE) -> 435 | F8: 2 | G8: 18 | H8: =F8*3+G8 -> 24 | J8: Fermanagh | K8: =HLOOKUP(J8,AA$1:CB$10081,ROW()-1,FALSE) -> 570 | L8: 1 | M8: 12 | N8: =L8*3+M8 -> 15 | P8: Y | R8: =MIN(Rules!$E$2,(MAX(H8/N8,N8/H8))) -> 1.6 | S8: =VLOOKUP(B8,Rules!A:B,2,FALSE) -> 40 | U8: =1/(10^(-(E8+(IF(P8="Y",Rules!$I$2,0))-K8)/Rules!$E$12)+1) -> 0.51726252 | V8: =ROUND(IF(H8>N8,(S8*R8*(1-U8)),IF(H8<N8,(S8*R8*(0-U8)),S8*R8*(0.5-U8))),0) -> 31 | W8: =-1*V8 -> -31 | AA8: =IF($D8=AA$1,$E8+$V8,(IF($J8=AA$1,$K8+$W8,AA7))) -> 1543 | AB8: =IF($D8=AB$1,$E8+$V8,(IF($J8=AB$1,$K8+$W8,AB7))) -> 605 | AC8: =IF($D8=AC$1,$E8+$V8,(IF($J8=AC$1,$K8+$W8,AC7))) -> 1440 | AD8: =IF($D8=AD$1,$E8+$V8,(IF($J8=AD$1,$K8+$W8,AD7))) -> 377 | AE8: =IF($D8=AE$1,$E8+$V8,(IF($J8=AE$1,$K8+$W8,AE7))) -> 2294 | AF8: =IF($D8=AF$1,$E8+$V8,(IF($J8=AF$1,$K8+$W8,AF7))) -> 2260 | AG8: =IF($D8=AG$1,$E8+$V8,(IF($J8=AG$1,$K8+$W8,AG7))) -> 1213 | AH8: =IF($D8=AH$1,$E8+$V8,(IF($J8=AH$1,$K8+$W8,AH7))) -> 1104 | ... BL8: =IF($D8=BL$1,$E8+$V8,(IF($J8=BL$1,$K8+$W8,BL7))) -> 822
A9: 45682 | B9: League | D9: Longford | E9: =HLOOKUP(D9,AA$1:CB$10081,ROW()-1,FALSE) -> 401 | F9: 4 | G9: 14 | H9: =F9*3+G9 -> 26 | J9: Warwickshire | K9: =HLOOKUP(J9,AA$1:CB$10081,ROW()-1,FALSE) -> 237 | L9: 3 | M9: 11 | N9: =L9*3+M9 -> 20 | P9: Y | R9: =MIN(Rules!$E$2,(MAX(H9/N9,N9/H9))) -> 1.3 | S9: =VLOOKUP(B9,Rules!A:B,2,FALSE) -> 40 | U9: =1/(10^(-(E9+(IF(P9="Y",Rules!$I$2,0))-K9)/Rules!$E$12)+1) -> 0.80938568 | V9: =ROUND(IF(H9>N9,(S9*R9*(1-U9)),IF(H9<N9,(S9*R9*(0-U9)),S9*R9*(0.5-U9))),0) -> 10 | W9: =-1*V9 -> -10 | AA9: =IF($D9=AA$1,$E9+$V9,(IF($J9=AA$1,$K9+$W9,AA8))) -> 1543 | AB9: =IF($D9=AB$1,$E9+$V9,(IF($J9=AB$1,$K9+$W9,AB8))) -> 605 | AC9: =IF($D9=AC$1,$E9+$V9,(IF($J9=AC$1,$K9+$W9,AC8))) -> 1440 | AD9: =IF($D9=AD$1,$E9+$V9,(IF($J9=AD$1,$K9+$W9,AD8))) -> 377 | AE9: =IF($D9=AE$1,$E9+$V9,(IF($J9=AE$1,$K9+$W9,AE8))) -> 2294 | AF9: =IF($D9=AF$1,$E9+$V9,(IF($J9=AF$1,$K9+$W9,AF8))) -> 2260 | AG9: =IF($D9=AG$1,$E9+$V9,(IF($J9=AG$1,$K9+$W9,AG8))) -> 1213 | AH9: =IF($D9=AH$1,$E9+$V9,(IF($J9=AH$1,$K9+$W9,AH8))) -> 1104 | ... BL9: =IF($D9=BL$1,$E9+$V9,(IF($J9=BL$1,$K9+$W9,BL8))) -> 822
A10: 45682 | B10: League | D10: Lancashire | E10: =HLOOKUP(D10,AA$1:CB$10081,ROW()-1,FALSE) -> 136 | F10: 2 | G10: 10 | H10: =F10*3+G10 -> 16 | J10: Leitrim | K10: =HLOOKUP(J10,AA$1:CB$10081,ROW()-1,FALSE) -> 228 | L10: 0 | M10: 21 | N10: =L10*3+M10 -> 21 | P10: N | R10: =MIN(Rules!$E$2,(MAX(H10/N10,N10/H10))) -> 1.3125 | S10: =VLOOKUP(B10,Rules!A:B,2,FALSE) -> 40 | U10: =1/(10^(-(E10+(IF(P10="Y",Rules!$I$2,0))-K10)/Rules!$E$12)+1) -> 0.39563753 | V10: =ROUND(IF(H10>N10,(S10*R10*(1-U10)),IF(H10<N10,(S10*R10*(0-U10)),S10*R10*(0.5-U10))),0) -> -21 | W10: =-1*V10 -> 21 | AA10: =IF($D10=AA$1,$E10+$V10,(IF($J10=AA$1,$K10+$W10,AA9))) -> 1543 | AB10: =IF($D10=AB$1,$E10+$V10,(IF($J10=AB$1,$K10+$W10,AB9))) -> 605 | AC10: =IF($D10=AC$1,$E10+$V10,(IF($J10=AC$1,$K10+$W10,AC9))) -> 1440 | AD10: =IF($D10=AD$1,$E10+$V10,(IF($J10=AD$1,$K10+$W10,AD9))) -> 377 | AE10: =IF($D10=AE$1,$E10+$V10,(IF($J10=AE$1,$K10+$W10,AE9))) -> 2294 | AF10: =IF($D10=AF$1,$E10+$V10,(IF($J10=AF$1,$K10+$W10,AF9))) -> 2260 | AG10: =IF($D10=AG$1,$E10+$V10,(IF($J10=AG$1,$K10+$W10,AG9))) -> 1213 | AH10: =IF($D10=AH$1,$E10+$V10,(IF($J10=AH$1,$K10+$W10,AH9))) -> 1104 | ... BL10: =IF($D10=BL$1,$E10+$V10,(IF($J10=BL$1,$K10+$W10,BL9))) -> 822
A11: 45682 | B11: League | D11: Meath | E11: =HLOOKUP(D11,AA$1:CB$10081,ROW()-1,FALSE) -> 1089 | F11: 2 | G11: 12 | H11: =F11*3+G11 -> 18 | J11: Donegal | K11: =HLOOKUP(J11,AA$1:CB$10081,ROW()-1,FALSE) -> 1104 | L11: 1 | M11: 14 | N11: =L11*3+M11 -> 17 | P11: Y | R11: =MIN(Rules!$E$2,(MAX(H11/N11,N11/H11))) -> 1.0588235 | S11: =VLOOKUP(B11,Rules!A:B,2,FALSE) -> 40 | U11: =1/(10^(-(E11+(IF(P11="Y",Rules!$I$2,0))-K11)/Rules!$E$12)+1) -> 0.65060463 | V11: =ROUND(IF(H11>N11,(S11*R11*(1-U11)),IF(H11<N11,(S11*R11*(0-U11)),S11*R11*(0.5-U11))),0) -> 15 | W11: =-1*V11 -> -15 | AA11: =IF($D11=AA$1,$E11+$V11,(IF($J11=AA$1,$K11+$W11,AA10))) -> 1543 | AB11: =IF($D11=AB$1,$E11+$V11,(IF($J11=AB$1,$K11+$W11,AB10))) -> 605 | AC11: =IF($D11=AC$1,$E11+$V11,(IF($J11=AC$1,$K11+$W11,AC10))) -> 1440 | AD11: =IF($D11=AD$1,$E11+$V11,(IF($J11=AD$1,$K11+$W11,AD10))) -> 377 | AE11: =IF($D11=AE$1,$E11+$V11,(IF($J11=AE$1,$K11+$W11,AE10))) -> 2294 | AF11: =IF($D11=AF$1,$E11+$V11,(IF($J11=AF$1,$K11+$W11,AF10))) -> 2260 | AG11: =IF($D11=AG$1,$E11+$V11,(IF($J11=AG$1,$K11+$W11,AG10))) -> 1213 | AH11: =IF($D11=AH$1,$E11+$V11,(IF($J11=AH$1,$K11+$W11,AH10))) -> 1089 | ... BL11: =IF($D11=BL$1,$E11+$V11,(IF($J11=BL$1,$K11+$W11,BL10))) -> 822
A12: 45683 | B12: League | D12: Clare | E12: =HLOOKUP(D12,AA$1:CB$10081,ROW()-1,FALSE) -> 2294 | F12: 0 | G12: 21 | H12: =F12*3+G12 -> 21 | J12: Kilkenny | K12: =HLOOKUP(J12,AA$1:CB$10081,ROW()-1,FALSE) -> 2115 | L12: 0 | M12: 23 | N12: =L12*3+M12 -> 23 | P12: Y | R12: =MIN(Rules!$E$2,(MAX(H12/N12,N12/H12))) -> 1.0952381 | S12: =VLOOKUP(B12,Rules!A:B,2,FALSE) -> 40 | U12: =1/(10^(-(E12+(IF(P12="Y",Rules!$I$2,0))-K12)/Rules!$E$12)+1) -> 0.81981594 | V12: =ROUND(IF(H12>N12,(S12*R12*(1-U12)),IF(H12<N12,(S12*R12*(0-U12)),S12*R12*(0.5-U12))),0) -> -36 | W12: =-1*V12 -> 36 | AA12: =IF($D12=AA$1,$E12+$V12,(IF($J12=AA$1,$K12+$W12,AA11))) -> 1543 | AB12: =IF($D12=AB$1,$E12+$V12,(IF($J12=AB$1,$K12+$W12,AB11))) -> 605 | AC12: =IF($D12=AC$1,$E12+$V12,(IF($J12=AC$1,$K12+$W12,AC11))) -> 1440 | AD12: =IF($D12=AD$1,$E12+$V12,(IF($J12=AD$1,$K12+$W12,AD11))) -> 377 | AE12: =IF($D12=AE$1,$E12+$V12,(IF($J12=AE$1,$K12+$W12,AE11))) -> 2258 | AF12: =IF($D12=AF$1,$E12+$V12,(IF($J12=AF$1,$K12+$W12,AF11))) -> 2260 | AG12: =IF($D12=AG$1,$E12+$V12,(IF($J12=AG$1,$K12+$W12,AG11))) -> 1213 | AH12: =IF($D12=AH$1,$E12+$V12,(IF($J12=AH$1,$K12+$W12,AH11))) -> 1089 | ... BL12: =IF($D12=BL$1,$E12+$V12,(IF($J12=BL$1,$K12+$W12,BL11))) -> 822
A13: 45683 | B13: League | D13: Galway | E13: =HLOOKUP(D13,AA$1:CB$10081,ROW()-1,FALSE) -> 2025 | F13: 2 | G13: 16 | H13: =F13*3+G13 -> 22 | J13: Tipperary | K13: =HLOOKUP(J13,AA$1:CB$10081,ROW()-1,FALSE) -> 1960 | L13: 3 | M13: 25 | N13: =L13*3+M13 -> 34 | P13: Y | R13: =MIN(Rules!$E$2,(MAX(H13/N13,N13/H13))) -> 1.5454545 | S13: =VLOOKUP(B13,Rules!A:B,2,FALSE) -> 40 | U13: =1/(10^(-(E13+(IF(P13="Y",Rules!$I$2,0))-K13)/Rules!$E$12)+1) -> 0.72910996 | V13: =ROUND(IF(H13>N13,(S13*R13*(1-U13)),IF(H13<N13,(S13*R13*(0-U13)),S13*R13*(0.5-U13))),0) -> -45 | W13: =-1*V13 -> 45 | AA13: =IF($D13=AA$1,$E13+$V13,(IF($J13=AA$1,$K13+$W13,AA12))) -> 1543 | AB13: =IF($D13=AB$1,$E13+$V13,(IF($J13=AB$1,$K13+$W13,AB12))) -> 605 | AC13: =IF($D13=AC$1,$E13+$V13,(IF($J13=AC$1,$K13+$W13,AC12))) -> 1440 | AD13: =IF($D13=AD$1,$E13+$V13,(IF($J13=AD$1,$K13+$W13,AD12))) -> 377 | AE13: =IF($D13=AE$1,$E13+$V13,(IF($J13=AE$1,$K13+$W13,AE12))) -> 2258 | AF13: =IF($D13=AF$1,$E13+$V13,(IF($J13=AF$1,$K13+$W13,AF12))) -> 2260 | AG13: =IF($D13=AG$1,$E13+$V13,(IF($J13=AG$1,$K13+$W13,AG12))) -> 1213 | AH13: =IF($D13=AH$1,$E13+$V13,(IF($J13=AH$1,$K13+$W13,AH12))) -> 1089 | ... BL13: =IF($D13=BL$1,$E13+$V13,(IF($J13=BL$1,$K13+$W13,BL12))) -> 822
A14: 45683 | B14: League | D14: London | E14: =HLOOKUP(D14,AA$1:CB$10081,ROW()-1,FALSE) -> 981 | F14: 1 | G14: 10 | H14: =F14*3+G14 -> 13 | J14: Roscommon | K14: =HLOOKUP(J14,AA$1:CB$10081,ROW()-1,FALSE) -> 798 | L14: 1 | M14: 15 | N14: =L14*3+M14 -> 18 | P14: Y | R14: =MIN(Rules!$E$2,(MAX(H14/N14,N14/H14))) -> 1.3846154 | S14: =VLOOKUP(B14,Rules!A:B,2,FALSE) -> 40 | U14: =1/(10^(-(E14+(IF(P14="Y",Rules!$I$2,0))-K14)/Rules!$E$12)+1) -> 0.82252099 | V14: =ROUND(IF(H14>N14,(S14*R14*(1-U14)),IF(H14<N14,(S14*R14*(0-U14)),S14*R14*(0.5-U14))),0) -> -46 | W14: =-1*V14 -> 46 | AA14: =IF($D14=AA$1,$E14+$V14,(IF($J14=AA$1,$K14+$W14,AA13))) -> 1543 | AB14: =IF($D14=AB$1,$E14+$V14,(IF($J14=AB$1,$K14+$W14,AB13))) -> 605 | AC14: =IF($D14=AC$1,$E14+$V14,(IF($J14=AC$1,$K14+$W14,AC13))) -> 1440 | AD14: =IF($D14=AD$1,$E14+$V14,(IF($J14=AD$1,$K14+$W14,AD13))) -> 377 | AE14: =IF($D14=AE$1,$E14+$V14,(IF($J14=AE$1,$K14+$W14,AE13))) -> 2258 | AF14: =IF($D14=AF$1,$E14+$V14,(IF($J14=AF$1,$K14+$W14,AF13))) -> 2260 | AG14: =IF($D14=AG$1,$E14+$V14,(IF($J14=AG$1,$K14+$W14,AG13))) -> 1213 | AH14: =IF($D14=AH$1,$E14+$V14,(IF($J14=AH$1,$K14+$W14,AH13))) -> 1089 | ... BL14: =IF($D14=BL$1,$E14+$V14,(IF($J14=BL$1,$K14+$W14,BL13))) -> 822
A15: 45683 | B15: League | D15: Sligo | E15: =HLOOKUP(D15,AA$1:CB$10081,ROW()-1,FALSE) -> 716 | F15: 2 | G15: 8 | H15: =F15*3+G15 -> 14 | J15: Wicklow | K15: =HLOOKUP(J15,AA$1:CB$10081,ROW()-1,FALSE) -> 822 | L15: 1 | M15: 16 | N15: =L15*3+M15 -> 19 | P15: Y | R15: =MIN(Rules!$E$2,(MAX(H15/N15,N15/H15))) -> 1.3571429 | S15: =VLOOKUP(B15,Rules!A:B,2,FALSE) -> 40 | U15: =1/(10^(-(E15+(IF(P15="Y",Rules!$I$2,0))-K15)/Rules!$E$12)+1) -> 0.55048426 | V15: =ROUND(IF(H15>N15,(S15*R15*(1-U15)),IF(H15<N15,(S15*R15*(0-U15)),S15*R15*(0.5-U15))),0) -> -30 | W15: =-1*V15 -> 30 | AA15: =IF($D15=AA$1,$E15+$V15,(IF($J15=AA$1,$K15+$W15,AA14))) -> 1543 | AB15: =IF($D15=AB$1,$E15+$V15,(IF($J15=AB$1,$K15+$W15,AB14))) -> 605 | AC15: =IF($D15=AC$1,$E15+$V15,(IF($J15=AC$1,$K15+$W15,AC14))) -> 1440 | AD15: =IF($D15=AD$1,$E15+$V15,(IF($J15=AD$1,$K15+$W15,AD14))) -> 377 | AE15: =IF($D15=AE$1,$E15+$V15,(IF($J15=AE$1,$K15+$W15,AE14))) -> 2258 | AF15: =IF($D15=AF$1,$E15+$V15,(IF($J15=AF$1,$K15+$W15,AF14))) -> 2260 | AG15: =IF($D15=AG$1,$E15+$V15,(IF($J15=AG$1,$K15+$W15,AG14))) -> 1213 | AH15: =IF($D15=AH$1,$E15+$V15,(IF($J15=AH$1,$K15+$W15,AH14))) -> 1089 | ... BL15: =IF($D15=BL$1,$E15+$V15,(IF($J15=BL$1,$K15+$W15,BL14))) -> 852
A16: 45704 | B16: League | D16: Westmeath | E16: =HLOOKUP(D16,AA$1:CB$10081,ROW()-1,FALSE) -> 1514 | F16: 0 | G16: 1 | H16: 19 | J16: Laois | K16: =HLOOKUP(J16,AA$1:CB$10081,ROW()-1,FALSE) -> 1521 | L16: 4 | M16: 18 | N16: =L16*3+M16 -> 30 | P16: Y | R16: =MIN(Rules!$E$2,(MAX(H16/N16,N16/H16))) -> 1.5789474 | S16: =VLOOKUP(B16,Rules!A:B,2,FALSE) -> 40 | U16: =1/(10^(-(E16+(IF(P16="Y",Rules!$I$2,0))-K16)/Rules!$E$12)+1) -> 0.65893219 | V16: =ROUND(IF(H16>N16,(S16*R16*(1-U16)),IF(H16<N16,(S16*R16*(0-U16)),S16*R16*(0.5-U16))),0) -> -42 | W16: =-1*V16 -> 42 | AA16: =IF($D16=AA$1,$E16+$V16,(IF($J16=AA$1,$K16+$W16,AA15))) -> 1543 | AB16: =IF($D16=AB$1,$E16+$V16,(IF($J16=AB$1,$K16+$W16,AB15))) -> 605 | AC16: =IF($D16=AC$1,$E16+$V16,(IF($J16=AC$1,$K16+$W16,AC15))) -> 1440 | AD16: =IF($D16=AD$1,$E16+$V16,(IF($J16=AD$1,$K16+$W16,AD15))) -> 377 | AE16: =IF($D16=AE$1,$E16+$V16,(IF($J16=AE$1,$K16+$W16,AE15))) -> 2258 | AF16: =IF($D16=AF$1,$E16+$V16,(IF($J16=AF$1,$K16+$W16,AF15))) -> 2260 | AG16: =IF($D16=AG$1,$E16+$V16,(IF($J16=AG$1,$K16+$W16,AG15))) -> 1213 | AH16: =IF($D16=AH$1,$E16+$V16,(IF($J16=AH$1,$K16+$W16,AH15))) -> 1089 | ... BL16: =IF($D16=BL$1,$E16+$V16,(IF($J16=BL$1,$K16+$W16,BL15))) -> 852
A17: 45704 | B17: League | D17: Mayo | E17: =HLOOKUP(D17,AA$1:CB$10081,ROW()-1,FALSE) -> 895 | F17: 1 | G17: 23 | H17: =F17*3+G17 -> 26 | J17: Cavan | K17: =HLOOKUP(J17,AA$1:CB$10081,ROW()-1,FALSE) -> 377 | L17: 2 | M17: 14 | N17: =L17*3+M17 -> 20 | P17: Y | R17: =MIN(Rules!$E$2,(MAX(H17/N17,N17/H17))) -> 1.3 | S17: =VLOOKUP(B17,Rules!A:B,2,FALSE) -> 40 | U17: =1/(10^(-(E17+(IF(P17="Y",Rules!$I$2,0))-K17)/Rules!$E$12)+1) -> 0.95590254 | V17: =ROUND(IF(H17>N17,(S17*R17*(1-U17)),IF(H17<N17,(S17*R17*(0-U17)),S17*R17*(0.5-U17))),0) -> 2 | W17: =-1*V17 -> -2 | AA17: =IF($D17=AA$1,$E17+$V17,(IF($J17=AA$1,$K17+$W17,AA16))) -> 1543 | AB17: =IF($D17=AB$1,$E17+$V17,(IF($J17=AB$1,$K17+$W17,AB16))) -> 605 | AC17: =IF($D17=AC$1,$E17+$V17,(IF($J17=AC$1,$K17+$W17,AC16))) -> 1440 | AD17: =IF($D17=AD$1,$E17+$V17,(IF($J17=AD$1,$K17+$W17,AD16))) -> 375 | AE17: =IF($D17=AE$1,$E17+$V17,(IF($J17=AE$1,$K17+$W17,AE16))) -> 2258 | AF17: =IF($D17=AF$1,$E17+$V17,(IF($J17=AF$1,$K17+$W17,AF16))) -> 2260 | AG17: =IF($D17=AG$1,$E17+$V17,(IF($J17=AG$1,$K17+$W17,AG16))) -> 1213 | AH17: =IF($D17=AH$1,$E17+$V17,(IF($J17=AH$1,$K17+$W17,AH16))) -> 1089 | ... BL17: =IF($D17=BL$1,$E17+$V17,(IF($J17=BL$1,$K17+$W17,BL16))) -> 852
A18: 45689 | B18: League | D18: Cork | E18: =HLOOKUP(D18,AA$1:CB$10081,ROW()-1,FALSE) -> 2260 | F18: 1 | G18: 16 | H18: =F18*3+G18 -> 19 | J18: Limerick | K18: =HLOOKUP(J18,AA$1:CB$10081,ROW()-1,FALSE) -> 2337 | L18: 1 | M18: 16 | N18: =L18*3+M18 -> 19 | P18: Y | R18: =MIN(Rules!$E$2,(MAX(H18/N18,N18/H18))) -> 1 | S18: =VLOOKUP(B18,Rules!A:B,2,FALSE) -> 40 | U18: =1/(10^(-(E18+(IF(P18="Y",Rules!$I$2,0))-K18)/Rules!$E$12)+1) -> 0.58326168 | V18: =ROUND(IF(H18>N18,(S18*R18*(1-U18)),IF(H18<N18,(S18*R18*(0-U18)),S18*R18*(0.5-U18))),0) -> -3 | W18: =-1*V18 -> 3 | AA18: =IF($D18=AA$1,$E18+$V18,(IF($J18=AA$1,$K18+$W18,AA17))) -> 1543 | AB18: =IF($D18=AB$1,$E18+$V18,(IF($J18=AB$1,$K18+$W18,AB17))) -> 605 | AC18: =IF($D18=AC$1,$E18+$V18,(IF($J18=AC$1,$K18+$W18,AC17))) -> 1440 | AD18: =IF($D18=AD$1,$E18+$V18,(IF($J18=AD$1,$K18+$W18,AD17))) -> 375 | AE18: =IF($D18=AE$1,$E18+$V18,(IF($J18=AE$1,$K18+$W18,AE17))) -> 2258 | AF18: =IF($D18=AF$1,$E18+$V18,(IF($J18=AF$1,$K18+$W18,AF17))) -> 2257 | AG18: =IF($D18=AG$1,$E18+$V18,(IF($J18=AG$1,$K18+$W18,AG17))) -> 1213 | AH18: =IF($D18=AH$1,$E18+$V18,(IF($J18=AH$1,$K18+$W18,AH17))) -> 1089 | ... BL18: =IF($D18=BL$1,$E18+$V18,(IF($J18=BL$1,$K18+$W18,BL17))) -> 852
A19: 45689 | B19: League | D19: Derry | E19: =HLOOKUP(D19,AA$1:CB$10081,ROW()-1,FALSE) -> 1213 | F19: 0 | G19: 13 | H19: =F19*3+G19 -> 13 | J19: Down | K19: =HLOOKUP(J19,AA$1:CB$10081,ROW()-1,FALSE) -> 1215 | L19: 2 | M19: 26 | N19: =L19*3+M19 -> 32 | P19: Y | R19: =MIN(Rules!$E$2,(MAX(H19/N19,N19/H19))) -> 2 | S19: =VLOOKUP(B19,Rules!A:B,2,FALSE) -> 40 | U19: =1/(10^(-(E19+(IF(P19="Y",Rules!$I$2,0))-K19)/Rules!$E$12)+1) -> 0.66408794 | V19: =ROUND(IF(H19>N19,(S19*R19*(1-U19)),IF(H19<N19,(S19*R19*(0-U19)),S19*R19*(0.5-U19))),0) -> -53 | W19: =-1*V19 -> 53 | AA19: =IF($D19=AA$1,$E19+$V19,(IF($J19=AA$1,$K19+$W19,AA18))) -> 1543 | AB19: =IF($D19=AB$1,$E19+$V19,(IF($J19=AB$1,$K19+$W19,AB18))) -> 605 | AC19: =IF($D19=AC$1,$E19+$V19,(IF($J19=AC$1,$K19+$W19,AC18))) -> 1440 | AD19: =IF($D19=AD$1,$E19+$V19,(IF($J19=AD$1,$K19+$W19,AD18))) -> 375 | AE19: =IF($D19=AE$1,$E19+$V19,(IF($J19=AE$1,$K19+$W19,AE18))) -> 2258 | AF19: =IF($D19=AF$1,$E19+$V19,(IF($J19=AF$1,$K19+$W19,AF18))) -> 2257 | AG19: =IF($D19=AG$1,$E19+$V19,(IF($J19=AG$1,$K19+$W19,AG18))) -> 1160 | AH19: =IF($D19=AH$1,$E19+$V19,(IF($J19=AH$1,$K19+$W19,AH18))) -> 1089 | ... BL19: =IF($D19=BL$1,$E19+$V19,(IF($J19=BL$1,$K19+$W19,BL18))) -> 852
A20: 45689 | B20: League | D20: Kildare | E20: =HLOOKUP(D20,AA$1:CB$10081,ROW()-1,FALSE) -> 1340 | F20: 2 | G20: 28 | H20: =F20*3+G20 -> 34 | J20: Kerry | K20: =HLOOKUP(J20,AA$1:CB$10081,ROW()-1,FALSE) -> 1331 | L20: 0 | M20: 17 | N20: =L20*3+M20 -> 17 | P20: Y | R20: =MIN(Rules!$E$2,(MAX(H20/N20,N20/H20))) -> 2 | S20: =VLOOKUP(B20,Rules!A:B,2,FALSE) -> 40 | U20: =1/(10^(-(E20+(IF(P20="Y",Rules!$I$2,0))-K20)/Rules!$E$12)+1) -> 0.6752927 | V20: =ROUND(IF(H20>N20,(S20*R20*(1-U20)),IF(H20<N20,(S20*R20*(0-U20)),S20*R20*(0.5-U20))),0) -> 26 | W20: =-1*V20 -> -26 | AA20: =IF($D20=AA$1,$E20+$V20,(IF($J20=AA$1,$K20+$W20,AA19))) -> 1543 | AB20: =IF($D20=AB$1,$E20+$V20,(IF($J20=AB$1,$K20+$W20,AB19))) -> 605 | AC20: =IF($D20=AC$1,$E20+$V20,(IF($J20=AC$1,$K20+$W20,AC19))) -> 1440 | AD20: =IF($D20=AD$1,$E20+$V20,(IF($J20=AD$1,$K20+$W20,AD19))) -> 375 | AE20: =IF($D20=AE$1,$E20+$V20,(IF($J20=AE$1,$K20+$W20,AE19))) -> 2258 | AF20: =IF($D20=AF$1,$E20+$V20,(IF($J20=AF$1,$K20+$W20,AF19))) -> 2257 | AG20: =IF($D20=AG$1,$E20+$V20,(IF($J20=AG$1,$K20+$W20,AG19))) -> 1160 | AH20: =IF($D20=AH$1,$E20+$V20,(IF($J20=AH$1,$K20+$W20,AH19))) -> 1089 | ... BL20: =IF($D20=BL$1,$E20+$V20,(IF($J20=BL$1,$K20+$W20,BL19))) -> 852
A21: 45689 | B21: League | D21: Cavan | E21: =HLOOKUP(D21,AA$1:CB$10081,ROW()-1,FALSE) -> 375 | F21: 1 | G21: 17 | H21: =F21*3+G21 -> 20 | J21: Sligo | K21: =HLOOKUP(J21,AA$1:CB$10081,ROW()-1,FALSE) -> 686 | L21: 1 | M21: 12 | N21: =L21*3+M21 -> 15 | P21: Y | R21: =MIN(Rules!$E$2,(MAX(H21/N21,N21/H21))) -> 1.3333333 | S21: =VLOOKUP(B21,Rules!A:B,2,FALSE) -> 40 | U21: =1/(10^(-(E21+(IF(P21="Y",Rules!$I$2,0))-K21)/Rules!$E$12)+1) -> 0.322691 | V21: =ROUND(IF(H21>N21,(S21*R21*(1-U21)),IF(H21<N21,(S21*R21*(0-U21)),S21*R21*(0.5-U21))),0) -> 36 | W21: =-1*V21 -> -36 | AA21: =IF($D21=AA$1,$E21+$V21,(IF($J21=AA$1,$K21+$W21,AA20))) -> 1543 | AB21: =IF($D21=AB$1,$E21+$V21,(IF($J21=AB$1,$K21+$W21,AB20))) -> 605 | AC21: =IF($D21=AC$1,$E21+$V21,(IF($J21=AC$1,$K21+$W21,AC20))) -> 1440 | AD21: =IF($D21=AD$1,$E21+$V21,(IF($J21=AD$1,$K21+$W21,AD20))) -> 411 | AE21: =IF($D21=AE$1,$E21+$V21,(IF($J21=AE$1,$K21+$W21,AE20))) -> 2258 | AF21: =IF($D21=AF$1,$E21+$V21,(IF($J21=AF$1,$K21+$W21,AF20))) -> 2257 | AG21: =IF($D21=AG$1,$E21+$V21,(IF($J21=AG$1,$K21+$W21,AG20))) -> 1160 | AH21: =IF($D21=AH$1,$E21+$V21,(IF($J21=AH$1,$K21+$W21,AH20))) -> 1089 | ... BL21: =IF($D21=BL$1,$E21+$V21,(IF($J21=BL$1,$K21+$W21,BL20))) -> 852
A22: 45689 | B22: League | D22: Wicklow | E22: =HLOOKUP(D22,AA$1:CB$10081,ROW()-1,FALSE) -> 852 | F22: 1 | G22: 17 | H22: =F22*3+G22 -> 20 | J22: London | K22: =HLOOKUP(J22,AA$1:CB$10081,ROW()-1,FALSE) -> 935 | L22: 1 | M22: 18 | N22: =L22*3+M22 -> 21 | P22: Y | R22: =MIN(Rules!$E$2,(MAX(H22/N22,N22/H22))) -> 1.05 | S22: =VLOOKUP(B22,Rules!A:B,2,FALSE) -> 40 | U22: =1/(10^(-(E22+(IF(P22="Y",Rules!$I$2,0))-K22)/Rules!$E$12)+1) -> 0.57653041 | V22: =ROUND(IF(H22>N22,(S22*R22*(1-U22)),IF(H22<N22,(S22*R22*(0-U22)),S22*R22*(0.5-U22))),0) -> -24 | W22: =-1*V22 -> 24 | AA22: =IF($D22=AA$1,$E22+$V22,(IF($J22=AA$1,$K22+$W22,AA21))) -> 1543 | AB22: =IF($D22=AB$1,$E22+$V22,(IF($J22=AB$1,$K22+$W22,AB21))) -> 605 | AC22: =IF($D22=AC$1,$E22+$V22,(IF($J22=AC$1,$K22+$W22,AC21))) -> 1440 | AD22: =IF($D22=AD$1,$E22+$V22,(IF($J22=AD$1,$K22+$W22,AD21))) -> 411 | AE22: =IF($D22=AE$1,$E22+$V22,(IF($J22=AE$1,$K22+$W22,AE21))) -> 2258 | AF22: =IF($D22=AF$1,$E22+$V22,(IF($J22=AF$1,$K22+$W22,AF21))) -> 2257 | AG22: =IF($D22=AG$1,$E22+$V22,(IF($J22=AG$1,$K22+$W22,AG21))) -> 1160 | AH22: =IF($D22=AH$1,$E22+$V22,(IF($J22=AH$1,$K22+$W22,AH21))) -> 1089 | ... BL22: =IF($D22=BL$1,$E22+$V22,(IF($J22=BL$1,$K22+$W22,BL21))) -> 828
A23: 45689 | B23: League | D23: Monaghan | E23: =HLOOKUP(D23,AA$1:CB$10081,ROW()-1,FALSE) -> 413 | F23: 0 | G23: 11 | H23: =F23*3+G23 -> 11 | J23: Louth | K23: =HLOOKUP(J23,AA$1:CB$10081,ROW()-1,FALSE) -> 466 | L23: 2 | M23: 23 | N23: =L23*3+M23 -> 29 | P23: Y | R23: =MIN(Rules!$E$2,(MAX(H23/N23,N23/H23))) -> 2 | S23: =VLOOKUP(B23,Rules!A:B,2,FALSE) -> 40 | U23: =1/(10^(-(E23+(IF(P23="Y",Rules!$I$2,0))-K23)/Rules!$E$12)+1) -> 0.6098547 | V23: =ROUND(IF(H23>N23,(S23*R23*(1-U23)),IF(H23<N23,(S23*R23*(0-U23)),S23*R23*(0.5-U23))),0) -> -49 | W23: =-1*V23 -> 49 | AA23: =IF($D23=AA$1,$E23+$V23,(IF($J23=AA$1,$K23+$W23,AA22))) -> 1543 | AB23: =IF($D23=AB$1,$E23+$V23,(IF($J23=AB$1,$K23+$W23,AB22))) -> 605 | AC23: =IF($D23=AC$1,$E23+$V23,(IF($J23=AC$1,$K23+$W23,AC22))) -> 1440 | AD23: =IF($D23=AD$1,$E23+$V23,(IF($J23=AD$1,$K23+$W23,AD22))) -> 411 | AE23: =IF($D23=AE$1,$E23+$V23,(IF($J23=AE$1,$K23+$W23,AE22))) -> 2258 | AF23: =IF($D23=AF$1,$E23+$V23,(IF($J23=AF$1,$K23+$W23,AF22))) -> 2257 | AG23: =IF($D23=AG$1,$E23+$V23,(IF($J23=AG$1,$K23+$W23,AG22))) -> 1160 | AH23: =IF($D23=AH$1,$E23+$V23,(IF($J23=AH$1,$K23+$W23,AH22))) -> 1089 | ... BL23: =IF($D23=BL$1,$E23+$V23,(IF($J23=BL$1,$K23+$W23,BL22))) -> 828
A24: 45690 | B24: League | D24: Tipperary | E24: =HLOOKUP(D24,AA$1:CB$10081,ROW()-1,FALSE) -> 2005 | F24: 1 | G24: 22 | H24: =F24*3+G24 -> 25 | J24: Wexford | K24: =HLOOKUP(J24,AA$1:CB$10081,ROW()-1,FALSE) -> 1921 | L24: 0 | M24: 19 | N24: =L24*3+M24 -> 19 | P24: Y | R24: =MIN(Rules!$E$2,(MAX(H24/N24,N24/H24))) -> 1.3157895 | S24: =VLOOKUP(B24,Rules!A:B,2,FALSE) -> 40 | U24: =1/(10^(-(E24+(IF(P24="Y",Rules!$I$2,0))-K24)/Rules!$E$12)+1) -> 0.7460414 | V24: =ROUND(IF(H24>N24,(S24*R24*(1-U24)),IF(H24<N24,(S24*R24*(0-U24)),S24*R24*(0.5-U24))),0) -> 13 | W24: =-1*V24 -> -13 | AA24: =IF($D24=AA$1,$E24+$V24,(IF($J24=AA$1,$K24+$W24,AA23))) -> 1543 | AB24: =IF($D24=AB$1,$E24+$V24,(IF($J24=AB$1,$K24+$W24,AB23))) -> 605 | AC24: =IF($D24=AC$1,$E24+$V24,(IF($J24=AC$1,$K24+$W24,AC23))) -> 1440 | AD24: =IF($D24=AD$1,$E24+$V24,(IF($J24=AD$1,$K24+$W24,AD23))) -> 411 | AE24: =IF($D24=AE$1,$E24+$V24,(IF($J24=AE$1,$K24+$W24,AE23))) -> 2258 | AF24: =IF($D24=AF$1,$E24+$V24,(IF($J24=AF$1,$K24+$W24,AF23))) -> 2257 | AG24: =IF($D24=AG$1,$E24+$V24,(IF($J24=AG$1,$K24+$W24,AG23))) -> 1160 | AH24: =IF($D24=AH$1,$E24+$V24,(IF($J24=AH$1,$K24+$W24,AH23))) -> 1089 | ... BL24: =IF($D24=BL$1,$E24+$V24,(IF($J24=BL$1,$K24+$W24,BL23))) -> 828
A25: 45690 | B25: League | D25: Kilkenny | E25: =HLOOKUP(D25,AA$1:CB$10081,ROW()-1,FALSE) -> 2151 | F25: 1 | G25: 19 | H25: =F25*3+G25 -> 22 | J25: Galway | K25: =HLOOKUP(J25,AA$1:CB$10081,ROW()-1,FALSE) -> 1980 | L25: 2 | M25: 19 | N25: =L25*3+M25 -> 25 | P25: Y | R25: =MIN(Rules!$E$2,(MAX(H25/N25,N25/H25))) -> 1.1363636 | S25: =VLOOKUP(B25,Rules!A:B,2,FALSE) -> 40 | U25: =1/(10^(-(E25+(IF(P25="Y",Rules!$I$2,0))-K25)/Rules!$E$12)+1) -> 0.81430956 | V25: =ROUND(IF(H25>N25,(S25*R25*(1-U25)),IF(H25<N25,(S25*R25*(0-U25)),S25*R25*(0.5-U25))),0) -> -37 | W25: =-1*V25 -> 37 | AA25: =IF($D25=AA$1,$E25+$V25,(IF($J25=AA$1,$K25+$W25,AA24))) -> 1543 | AB25: =IF($D25=AB$1,$E25+$V25,(IF($J25=AB$1,$K25+$W25,AB24))) -> 605 | AC25: =IF($D25=AC$1,$E25+$V25,(IF($J25=AC$1,$K25+$W25,AC24))) -> 1440 | AD25: =IF($D25=AD$1,$E25+$V25,(IF($J25=AD$1,$K25+$W25,AD24))) -> 411 | AE25: =IF($D25=AE$1,$E25+$V25,(IF($J25=AE$1,$K25+$W25,AE24))) -> 2258 | AF25: =IF($D25=AF$1,$E25+$V25,(IF($J25=AF$1,$K25+$W25,AF24))) -> 2257 | AG25: =IF($D25=AG$1,$E25+$V25,(IF($J25=AG$1,$K25+$W25,AG24))) -> 1160 | AH25: =IF($D25=AH$1,$E25+$V25,(IF($J25=AH$1,$K25+$W25,AH24))) -> 1089 | ... BL25: =IF($D25=BL$1,$E25+$V25,(IF($J25=BL$1,$K25+$W25,BL24))) -> 828
A26: 45690 | B26: League | D26: Antrim | E26: =HLOOKUP(D26,AA$1:CB$10081,ROW()-1,FALSE) -> 1543 | F26: 2 | G26: 25 | H26: =F26*3+G26 -> 31 | J26: Westmeath | K26: =HLOOKUP(J26,AA$1:CB$10081,ROW()-1,FALSE) -> 1472 | L26: 1 | M26: 19 | N26: =L26*3+M26 -> 22 | P26: Y | R26: =MIN(Rules!$E$2,(MAX(H26/N26,N26/H26))) -> 1.4090909 | S26: =VLOOKUP(B26,Rules!A:B,2,FALSE) -> 40 | U26: =1/(10^(-(E26+(IF(P26="Y",Rules!$I$2,0))-K26)/Rules!$E$12)+1) -> 0.73453265 | V26: =ROUND(IF(H26>N26,(S26*R26*(1-U26)),IF(H26<N26,(S26*R26*(0-U26)),S26*R26*(0.5-U26))),0) -> 15 | W26: =-1*V26 -> -15 | AA26: =IF($D26=AA$1,$E26+$V26,(IF($J26=AA$1,$K26+$W26,AA25))) -> 1558 | AB26: =IF($D26=AB$1,$E26+$V26,(IF($J26=AB$1,$K26+$W26,AB25))) -> 605 | AC26: =IF($D26=AC$1,$E26+$V26,(IF($J26=AC$1,$K26+$W26,AC25))) -> 1440 | AD26: =IF($D26=AD$1,$E26+$V26,(IF($J26=AD$1,$K26+$W26,AD25))) -> 411 | AE26: =IF($D26=AE$1,$E26+$V26,(IF($J26=AE$1,$K26+$W26,AE25))) -> 2258 | AF26: =IF($D26=AF$1,$E26+$V26,(IF($J26=AF$1,$K26+$W26,AF25))) -> 2257 | AG26: =IF($D26=AG$1,$E26+$V26,(IF($J26=AG$1,$K26+$W26,AG25))) -> 1160 | AH26: =IF($D26=AH$1,$E26+$V26,(IF($J26=AH$1,$K26+$W26,AH25))) -> 1089 | ... BL26: =IF($D26=BL$1,$E26+$V26,(IF($J26=BL$1,$K26+$W26,BL25))) -> 828
A27: 45690 | B27: League | D27: Laois | E27: =HLOOKUP(D27,AA$1:CB$10081,ROW()-1,FALSE) -> 1563 | F27: 1 | G27: 15 | H27: =F27*3+G27 -> 18 | J27: Offaly | K27: =HLOOKUP(J27,AA$1:CB$10081,ROW()-1,FALSE) -> 1580 | L27: 1 | M27: 24 | N27: =L27*3+M27 -> 27 | P27: Y | R27: =MIN(Rules!$E$2,(MAX(H27/N27,N27/H27))) -> 1.5 | S27: =VLOOKUP(B27,Rules!A:B,2,FALSE) -> 40 | U27: =1/(10^(-(E27+(IF(P27="Y",Rules!$I$2,0))-K27)/Rules!$E$12)+1) -> 0.64850806 | V27: =ROUND(IF(H27>N27,(S27*R27*(1-U27)),IF(H27<N27,(S27*R27*(0-U27)),S27*R27*(0.5-U27))),0) -> -39 | W27: =-1*V27 -> 39 | AA27: =IF($D27=AA$1,$E27+$V27,(IF($J27=AA$1,$K27+$W27,AA26))) -> 1558 | AB27: =IF($D27=AB$1,$E27+$V27,(IF($J27=AB$1,$K27+$W27,AB26))) -> 605 | AC27: =IF($D27=AC$1,$E27+$V27,(IF($J27=AC$1,$K27+$W27,AC26))) -> 1440 | AD27: =IF($D27=AD$1,$E27+$V27,(IF($J27=AD$1,$K27+$W27,AD26))) -> 411 | AE27: =IF($D27=AE$1,$E27+$V27,(IF($J27=AE$1,$K27+$W27,AE26))) -> 2258 | AF27: =IF($D27=AF$1,$E27+$V27,(IF($J27=AF$1,$K27+$W27,AF26))) -> 2257 | AG27: =IF($D27=AG$1,$E27+$V27,(IF($J27=AG$1,$K27+$W27,AG26))) -> 1160 | AH27: =IF($D27=AH$1,$E27+$V27,(IF($J27=AH$1,$K27+$W27,AH26))) -> 1089 | ... BL27: =IF($D27=BL$1,$E27+$V27,(IF($J27=BL$1,$K27+$W27,BL26))) -> 828
A28: 45690 | B28: League | D28: Carlow | E28: =HLOOKUP(D28,AA$1:CB$10081,ROW()-1,FALSE) -> 1440 | F28: 2 | G28: 21 | H28: =F28*3+G28 -> 27 | J28: Waterford | K28: =HLOOKUP(J28,AA$1:CB$10081,ROW()-1,FALSE) -> 1920 | L28: 1 | M28: 19 | N28: =L28*3+M28 -> 22 | P28: Y | R28: =MIN(Rules!$E$2,(MAX(H28/N28,N28/H28))) -> 1.2272727 | S28: =VLOOKUP(B28,Rules!A:B,2,FALSE) -> 40 | U28: =1/(10^(-(E28+(IF(P28="Y",Rules!$I$2,0))-K28)/Rules!$E$12)+1) -> 0.17950479 | V28: =ROUND(IF(H28>N28,(S28*R28*(1-U28)),IF(H28<N28,(S28*R28*(0-U28)),S28*R28*(0.5-U28))),0) -> 40 | W28: =-1*V28 -> -40 | AA28: =IF($D28=AA$1,$E28+$V28,(IF($J28=AA$1,$K28+$W28,AA27))) -> 1558 | AB28: =IF($D28=AB$1,$E28+$V28,(IF($J28=AB$1,$K28+$W28,AB27))) -> 605 | AC28: =IF($D28=AC$1,$E28+$V28,(IF($J28=AC$1,$K28+$W28,AC27))) -> 1480 | AD28: =IF($D28=AD$1,$E28+$V28,(IF($J28=AD$1,$K28+$W28,AD27))) -> 411 | AE28: =IF($D28=AE$1,$E28+$V28,(IF($J28=AE$1,$K28+$W28,AE27))) -> 2258 | AF28: =IF($D28=AF$1,$E28+$V28,(IF($J28=AF$1,$K28+$W28,AF27))) -> 2257 | AG28: =IF($D28=AG$1,$E28+$V28,(IF($J28=AG$1,$K28+$W28,AG27))) -> 1160 | AH28: =IF($D28=AH$1,$E28+$V28,(IF($J28=AH$1,$K28+$W28,AH27))) -> 1089 | ... BL28: =IF($D28=BL$1,$E28+$V28,(IF($J28=BL$1,$K28+$W28,BL27))) -> 828
... A145: 45787 | B145: Provincial | D145: Clare | E145: =HLOOKUP(D145,AA$1:CB$10081,ROW()-1,FALSE) -> 2096 | F145: 2 | G145: 21 | H145: =F145*3+G145 -> 27 | J145: Tipperary | K145: =HLOOKUP(J145,AA$1:CB$10081,ROW()-1,FALSE) -> 2075 | L145: 4 | M145: 18 | N145: =L145*3+M145 -> 30 | P145: Y | R145: =MIN(Rules!$E$2,(MAX(H145/N145,N145/H145))) -> 1.1111111 | S145: =VLOOKUP(B145,Rules!A:B,2,FALSE) -> 60 | U145: =1/(10^(-(E145+(IF(P145="Y",Rules!$I$2,0))-K145)/Rules!$E$12)+1) -> 0.68729086 | V145: =ROUND(IF(H145>N145,(S145*R145*(1-U145)),IF(H145<N145,(S145*R145*(0-U145)),S145*R145*(0.5-U145))),0) -> -46 | W145: =-1*V145 -> 46 | AA145: =IF($D145=AA$1,$E145+$V145,(IF($J145=AA$1,$K145+$W145,AA144))) -> 1525 | AB145: =IF($D145=AB$1,$E145+$V145,(IF($J145=AB$1,$K145+$W145,AB144))) -> 585 | AC145: =IF($D145=AC$1,$E145+$V145,(IF($J145=AC$1,$K145+$W145,AC144))) -> 1536 | AD145: =IF($D145=AD$1,$E145+$V145,(IF($J145=AD$1,$K145+$W145,AD144))) -> 489 | AE145: =IF($D145=AE$1,$E145+$V145,(IF($J145=AE$1,$K145+$W145,AE144))) -> 2050 | AF145: =IF($D145=AF$1,$E145+$V145,(IF($J145=AF$1,$K145+$W145,AF144))) -> 2308 | AG145: =IF($D145=AG$1,$E145+$V145,(IF($J145=AG$1,$K145+$W145,AG144))) -> 1181 | AH145: =IF($D145=AH$1,$E145+$V145,(IF($J145=AH$1,$K145+$W145,AH144))) -> 1042 | ... BL145: =IF($D145=BL$1,$E145+$V145,(IF($J145=BL$1,$K145+$W145,BL144))) -> 872
A146: 45787 | B146: Provincial | D146: Kilkenny | E146: =HLOOKUP(D146,AA$1:CB$10081,ROW()-1,FALSE) -> 2167 | F146: 4 | G146: 25 | H146: =F146*3+G146 -> 37 | J146: Offaly | K146: =HLOOKUP(J146,AA$1:CB$10081,ROW()-1,FALSE) -> 1623 | L146: 2 | M146: 16 | N146: =L146*3+M146 -> 22 | P146: Y | R146: =MIN(Rules!$E$2,(MAX(H146/N146,N146/H146))) -> 1.6818182 | S146: =VLOOKUP(B146,Rules!A:B,2,FALSE) -> 60 | U146: =1/(10^(-(E146+(IF(P146="Y",Rules!$I$2,0))-K146)/Rules!$E$12)+1) -> 0.96068302 | V146: =ROUND(IF(H146>N146,(S146*R146*(1-U146)),IF(H146<N146,(S146*R146*(0-U146)),S146*R146*(0.5-U146))),0) -> 4 | W146: =-1*V146 -> -4 | AA146: =IF($D146=AA$1,$E146+$V146,(IF($J146=AA$1,$K146+$W146,AA144))) -> 1525 | AB146: =IF($D146=AB$1,$E146+$V146,(IF($J146=AB$1,$K146+$W146,AB144))) -> 585 | AC146: =IF($D146=AC$1,$E146+$V146,(IF($J146=AC$1,$K146+$W146,AC144))) -> 1536 | AD146: =IF($D146=AD$1,$E146+$V146,(IF($J146=AD$1,$K146+$W146,AD144))) -> 489 | AE146: =IF($D146=AE$1,$E146+$V146,(IF($J146=AE$1,$K146+$W146,AE144))) -> 2096 | AF146: =IF($D146=AF$1,$E146+$V146,(IF($J146=AF$1,$K146+$W146,AF144))) -> 2308 | AG146: =IF($D146=AG$1,$E146+$V146,(IF($J146=AG$1,$K146+$W146,AG144))) -> 1181 | AH146: =IF($D146=AH$1,$E146+$V146,(IF($J146=AH$1,$K146+$W146,AH144))) -> 1042 | ... BL146: =IF($D146=BL$1,$E146+$V146,(IF($J146=BL$1,$K146+$W146,BL144))) -> 872
A147: 45787 | B147: Provincial | D147: Antrim | E147: =HLOOKUP(D147,AA$1:CB$10081,ROW()-1,FALSE) -> 1525 | F147: 0 | G147: 19 | H147: =F147*3+G147 -> 19 | J147: Dublin | K147: =HLOOKUP(J147,AA$1:CB$10081,ROW()-1,FALSE) -> 1906 | L147: 3 | M147: 25 | N147: =L147*3+M147 -> 34 | P147: Y | R147: =MIN(Rules!$E$2,(MAX(H147/N147,N147/H147))) -> 1.7894737 | S147: =VLOOKUP(B147,Rules!A:B,2,FALSE) -> 60 | U147: =1/(10^(-(E147+(IF(P147="Y",Rules!$I$2,0))-K147)/Rules!$E$12)+1) -> 0.25658502 | V147: =ROUND(IF(H147>N147,(S147*R147*(1-U147)),IF(H147<N147,(S147*R147*(0-U147)),S147*R147*(0.5-U147))),0) -> -28 | W147: =-1*V147 -> 28 | AA147: =IF($D147=AA$1,$E147+$V147,(IF($J147=AA$1,$K147+$W147,AA146))) -> 1497 | AB147: =IF($D147=AB$1,$E147+$V147,(IF($J147=AB$1,$K147+$W147,AB146))) -> 585 | AC147: =IF($D147=AC$1,$E147+$V147,(IF($J147=AC$1,$K147+$W147,AC146))) -> 1536 | AD147: =IF($D147=AD$1,$E147+$V147,(IF($J147=AD$1,$K147+$W147,AD146))) -> 489 | AE147: =IF($D147=AE$1,$E147+$V147,(IF($J147=AE$1,$K147+$W147,AE146))) -> 2096 | AF147: =IF($D147=AF$1,$E147+$V147,(IF($J147=AF$1,$K147+$W147,AF146))) -> 2308 | AG147: =IF($D147=AG$1,$E147+$V147,(IF($J147=AG$1,$K147+$W147,AG146))) -> 1181 | AH147: =IF($D147=AH$1,$E147+$V147,(IF($J147=AH$1,$K147+$W147,AH146))) -> 1042 | ... BL147: =IF($D147=BL$1,$E147+$V147,(IF($J147=BL$1,$K147+$W147,BL146))) -> 872
A148: 45787 | B148: Provincial | D148: Galway | E148: =HLOOKUP(D148,AA$1:CB$10081,ROW()-1,FALSE) -> 2040 | F148: 1 | G148: 29 | H148: =F148*3+G148 -> 32 | J148: Wexford | K148: =HLOOKUP(J148,AA$1:CB$10081,ROW()-1,FALSE) -> 1954 | L148: 2 | M148: 16 | N148: =L148*3+M148 -> 22 | P148: Y | R148: =MIN(Rules!$E$2,(MAX(H148/N148,N148/H148))) -> 1.4545455 | S148: =VLOOKUP(B148,Rules!A:B,2,FALSE) -> 60 | U148: =1/(10^(-(E148+(IF(P148="Y",Rules!$I$2,0))-K148)/Rules!$E$12)+1) -> 0.74778246 | V148: =ROUND(IF(H148>N148,(S148*R148*(1-U148)),IF(H148<N148,(S148*R148*(0-U148)),S148*R148*(0.5-U148))),0) -> 22 | W148: =-1*V148 -> -22 | AA148: =IF($D148=AA$1,$E148+$V148,(IF($J148=AA$1,$K148+$W148,AA147))) -> 1497 | AB148: =IF($D148=AB$1,$E148+$V148,(IF($J148=AB$1,$K148+$W148,AB147))) -> 585 | AC148: =IF($D148=AC$1,$E148+$V148,(IF($J148=AC$1,$K148+$W148,AC147))) -> 1536 | AD148: =IF($D148=AD$1,$E148+$V148,(IF($J148=AD$1,$K148+$W148,AD147))) -> 489 | AE148: =IF($D148=AE$1,$E148+$V148,(IF($J148=AE$1,$K148+$W148,AE147))) -> 2096 | AF148: =IF($D148=AF$1,$E148+$V148,(IF($J148=AF$1,$K148+$W148,AF147))) -> 2308 | AG148: =IF($D148=AG$1,$E148+$V148,(IF($J148=AG$1,$K148+$W148,AG147))) -> 1181 | AH148: =IF($D148=AH$1,$E148+$V148,(IF($J148=AH$1,$K148+$W148,AH147))) -> 1042 | ... BL148: =IF($D148=BL$1,$E148+$V148,(IF($J148=BL$1,$K148+$W148,BL147))) -> 872
A149: 45787 | B149: Secondary | D149: Westmeath | E149: =HLOOKUP(D149,AA$1:CB$10081,ROW()-1,FALSE) -> 1407 | F149: 2 | G149: 24 | H149: =F149*3+G149 -> 30 | J149: Down | K149: =HLOOKUP(J149,AA$1:CB$10081,ROW()-1,FALSE) -> 1254 | L149: 0 | M149: 20 | N149: =L149*3+M149 -> 20 | P149: Y | R149: =MIN(Rules!$E$2,(MAX(H149/N149,N149/H149))) -> 1.5 | S149: =VLOOKUP(B149,Rules!A:B,2,FALSE) -> 50 | U149: =1/(10^(-(E149+(IF(P149="Y",Rules!$I$2,0))-K149)/Rules!$E$12)+1) -> 0.8014476 | V149: =ROUND(IF(H149>N149,(S149*R149*(1-U149)),IF(H149<N149,(S149*R149*(0-U149)),S149*R149*(0.5-U149))),0) -> 15 | W149: =-1*V149 -> -15 | AA149: =IF($D149=AA$1,$E149+$V149,(IF($J149=AA$1,$K149+$W149,AA148))) -> 1497 | AB149: =IF($D149=AB$1,$E149+$V149,(IF($J149=AB$1,$K149+$W149,AB148))) -> 585 | AC149: =IF($D149=AC$1,$E149+$V149,(IF($J149=AC$1,$K149+$W149,AC148))) -> 1536 | AD149: =IF($D149=AD$1,$E149+$V149,(IF($J149=AD$1,$K149+$W149,AD148))) -> 489 | AE149: =IF($D149=AE$1,$E149+$V149,(IF($J149=AE$1,$K149+$W149,AE148))) -> 2096 | AF149: =IF($D149=AF$1,$E149+$V149,(IF($J149=AF$1,$K149+$W149,AF148))) -> 2308 | AG149: =IF($D149=AG$1,$E149+$V149,(IF($J149=AG$1,$K149+$W149,AG148))) -> 1181 | AH149: =IF($D149=AH$1,$E149+$V149,(IF($J149=AH$1,$K149+$W149,AH148))) -> 1042 | ... BL149: =IF($D149=BL$1,$E149+$V149,(IF($J149=BL$1,$K149+$W149,BL148))) -> 872
A150: 45787 | B150: Secondary | D150: Carlow | E150: =HLOOKUP(D150,AA$1:CB$10081,ROW()-1,FALSE) -> 1536 | F150: 1 | G150: 20 | H150: =F150*3+G150 -> 23 | J150: Kildare | K150: =HLOOKUP(J150,AA$1:CB$10081,ROW()-1,FALSE) -> 1381 | L150: 2 | M150: 23 | N150: =L150*3+M150 -> 29 | P150: Y | R150: =MIN(Rules!$E$2,(MAX(H150/N150,N150/H150))) -> 1.2608696 | S150: =VLOOKUP(B150,Rules!A:B,2,FALSE) -> 50 | U150: =1/(10^(-(E150+(IF(P150="Y",Rules!$I$2,0))-K150)/Rules!$E$12)+1) -> 0.80290917 | V150: =ROUND(IF(H150>N150,(S150*R150*(1-U150)),IF(H150<N150,(S150*R150*(0-U150)),S150*R150*(0.5-U150))),0) -> -51 | W150: =-1*V150 -> 51 | AA150: =IF($D150=AA$1,$E150+$V150,(IF($J150=AA$1,$K150+$W150,AA149))) -> 1497 | AB150: =IF($D150=AB$1,$E150+$V150,(IF($J150=AB$1,$K150+$W150,AB149))) -> 585 | AC150: =IF($D150=AC$1,$E150+$V150,(IF($J150=AC$1,$K150+$W150,AC149))) -> 1485 | AD150: =IF($D150=AD$1,$E150+$V150,(IF($J150=AD$1,$K150+$W150,AD149))) -> 489 | AE150: =IF($D150=AE$1,$E150+$V150,(IF($J150=AE$1,$K150+$W150,AE149))) -> 2096 | AF150: =IF($D150=AF$1,$E150+$V150,(IF($J150=AF$1,$K150+$W150,AF149))) -> 2308 | AG150: =IF($D150=AG$1,$E150+$V150,(IF($J150=AG$1,$K150+$W150,AG149))) -> 1181 | AH150: =IF($D150=AH$1,$E150+$V150,(IF($J150=AH$1,$K150+$W150,AH149))) -> 1042 | ... BL150: =IF($D150=BL$1,$E150+$V150,(IF($J150=BL$1,$K150+$W150,BL149))) -> 872
A151: 45787 | B151: Secondary | D151: Wicklow | E151: =HLOOKUP(D151,AA$1:CB$10081,ROW()-1,FALSE) -> 872 | F151: 3 | G151: 17 | H151: =F151*3+G151 -> 26 | J151: Meath | K151: =HLOOKUP(J151,AA$1:CB$10081,ROW()-1,FALSE) -> 1105 | L151: 0 | M151: 16 | N151: =L151*3+M151 -> 16 | P151: Y | R151: =MIN(Rules!$E$2,(MAX(H151/N151,N151/H151))) -> 1.625 | S151: =VLOOKUP(B151,Rules!A:B,2,FALSE) -> 50 | U151: =1/(10^(-(E151+(IF(P151="Y",Rules!$I$2,0))-K151)/Rules!$E$12)+1) -> 0.40558937 | V151: =ROUND(IF(H151>N151,(S151*R151*(1-U151)),IF(H151<N151,(S151*R151*(0-U151)),S151*R151*(0.5-U151))),0) -> 48 | W151: =-1*V151 -> -48 | AA151: =IF($D151=AA$1,$E151+$V151,(IF($J151=AA$1,$K151+$W151,AA150))) -> 1497 | AB151: =IF($D151=AB$1,$E151+$V151,(IF($J151=AB$1,$K151+$W151,AB150))) -> 585 | AC151: =IF($D151=AC$1,$E151+$V151,(IF($J151=AC$1,$K151+$W151,AC150))) -> 1485 | AD151: =IF($D151=AD$1,$E151+$V151,(IF($J151=AD$1,$K151+$W151,AD150))) -> 489 | AE151: =IF($D151=AE$1,$E151+$V151,(IF($J151=AE$1,$K151+$W151,AE150))) -> 2096 | AF151: =IF($D151=AF$1,$E151+$V151,(IF($J151=AF$1,$K151+$W151,AF150))) -> 2308 | AG151: =IF($D151=AG$1,$E151+$V151,(IF($J151=AG$1,$K151+$W151,AG150))) -> 1181 | AH151: =IF($D151=AH$1,$E151+$V151,(IF($J151=AH$1,$K151+$W151,AH150))) -> 1042 | ... BL151: =IF($D151=BL$1,$E151+$V151,(IF($J151=BL$1,$K151+$W151,BL150))) -> 920
A152: 45787 | B152: Secondary | D152: Tyrone | E152: =HLOOKUP(D152,AA$1:CB$10081,ROW()-1,FALSE) -> 742 | F152: 0 | G152: 11 | H152: =F152*3+G152 -> 11 | J152: Derry | K152: =HLOOKUP(J152,AA$1:CB$10081,ROW()-1,FALSE) -> 1181 | L152: 1 | M152: 30 | N152: =L152*3+M152 -> 33 | P152: Y | R152: =MIN(Rules!$E$2,(MAX(H152/N152,N152/H152))) -> 2 | S152: =VLOOKUP(B152,Rules!A:B,2,FALSE) -> 50 | U152: =1/(10^(-(E152+(IF(P152="Y",Rules!$I$2,0))-K152)/Rules!$E$12)+1) -> 0.2090115 | V152: =ROUND(IF(H152>N152,(S152*R152*(1-U152)),IF(H152<N152,(S152*R152*(0-U152)),S152*R152*(0.5-U152))),0) -> -21 | W152: =-1*V152 -> 21 | AA152: =IF($D152=AA$1,$E152+$V152,(IF($J152=AA$1,$K152+$W152,AA151))) -> 1497 | AB152: =IF($D152=AB$1,$E152+$V152,(IF($J152=AB$1,$K152+$W152,AB151))) -> 585 | AC152: =IF($D152=AC$1,$E152+$V152,(IF($J152=AC$1,$K152+$W152,AC151))) -> 1485 | AD152: =IF($D152=AD$1,$E152+$V152,(IF($J152=AD$1,$K152+$W152,AD151))) -> 489 | AE152: =IF($D152=AE$1,$E152+$V152,(IF($J152=AE$1,$K152+$W152,AE151))) -> 2096 | AF152: =IF($D152=AF$1,$E152+$V152,(IF($J152=AF$1,$K152+$W152,AF151))) -> 2308 | AG152: =IF($D152=AG$1,$E152+$V152,(IF($J152=AG$1,$K152+$W152,AG151))) -> 1202 | AH152: =IF($D152=AH$1,$E152+$V152,(IF($J152=AH$1,$K152+$W152,AH151))) -> 1042 | ... BL152: =IF($D152=BL$1,$E152+$V152,(IF($J152=BL$1,$K152+$W152,BL151))) -> 920
